<?xml version="1.0" ?>
<robot name="new_ragdoll">
  <joint name="new_ragdoll__l_thigh_joint" type="revolute">
    <parent link="new_ragdoll__lower_body"/>
    <child link="new_ragdoll__v_l_thigh"/>
    <origin rpy="0   -1.57  0" xyz="-0.0864    0       10.00006"/>
    <axis xyz="0  0  1"/>
    <limit effort="0.0" lower="-2.051" upper="0.785" velocity="0.0"/>
  </joint>
  <joint name="new_ragdoll__L_thigh_joint2" type="fixed">
    <parent link="new_ragdoll__v_l_thigh"/>
    <child link="new_ragdoll__l_thigh"/>
    <origin rpy="0  0  0" xyz="0  0  0"/>
    <axis xyz="0  1  0"/>
    <limit effort="0.0" lower="0.0" upper="0.0" velocity="0.0"/>
  </joint>
  <joint name="new_ragdoll__l_shin_joint" type="revolute">
    <parent link="new_ragdoll__l_thigh"/>
    <child link="new_ragdoll__l_shin"/>
    <origin rpy="0  0  0" xyz="-0.42672  0       0"/>
    <axis xyz="0  0  1"/>
    <limit effort="0.0" lower="0.0" upper="1.824" velocity="0.0"/>
  </joint>
  <joint name="new_ragdoll__l_foot_joint" type="revolute">
    <parent link="new_ragdoll__l_shin"/>
    <child link="new_ragdoll__l_foot"/>
    <origin rpy="0  0  0" xyz="-0.41402  0       0"/>
    <axis xyz="0  0  1"/>
    <limit effort="0.0" lower="-0.41" upper="0.633" velocity="0.0"/>
  </joint>
  <joint name="new_ragdoll__r_thigh_joint" type="revolute">
    <parent link="new_ragdoll__lower_body"/>
    <child link="new_ragdoll__v_r_thigh"/>
    <origin rpy="0   -1.57  0" xyz="0.0864   0       9.99993"/>
    <axis xyz="0  0  1"/>
    <limit effort="0.0" lower="-2.051" upper="0.785" velocity="0.0"/>
  </joint>
  <joint name="new_ragdoll__R_thigh_joint2" type="fixed">
    <parent link="new_ragdoll__v_r_thigh"/>
    <child link="new_ragdoll__r_thigh"/>
    <origin rpy="0  0  0" xyz="0  0  0"/>
    <axis xyz="0  1  0"/>
    <limit effort="0.0" lower="0.0" upper="0.0" velocity="0.0"/>
  </joint>
  <joint name="new_ragdoll__r_shin_joint" type="revolute">
    <parent link="new_ragdoll__r_thigh"/>
    <child link="new_ragdoll__r_shin"/>
    <origin rpy="0  0  0" xyz="-0.42672  0       0"/>
    <axis xyz="0  0  1"/>
    <limit effort="0.0" lower="0.0" upper="1.824" velocity="0.0"/>
  </joint>
  <joint name="new_ragdoll__r_foot_joint" type="revolute">
    <parent link="new_ragdoll__r_shin"/>
    <child link="new_ragdoll__r_foot"/>
    <origin rpy="0  0  0" xyz="-0.41402  0       0"/>
    <axis xyz="0  0  1"/>
    <limit effort="0.0" lower="-0.41" upper="0.633" velocity="0.0"/>
  </joint>
  <joint name="new_ragdoll__middle_body_joint" type="revolute">
    <parent link="new_ragdoll__lower_body"/>
    <child link="new_ragdoll__middle_body"/>
    <origin rpy="0   -1.57  0" xyz="4.00000000e-05   0.00000000e+00   1.00520700e+01"/>
    <axis xyz="0  0  1"/>
    <limit effort="0.0" lower="-0.262" upper="0.611" velocity="0.0"/>
  </joint>
  <joint name="new_ragdoll__upper_body_joint" type="revolute">
    <parent link="new_ragdoll__middle_body"/>
    <child link="new_ragdoll__upper_body"/>
    <origin rpy="0  0  0" xyz="0.15112  0       0"/>
    <axis xyz="0  0  1"/>
    <limit effort="0.0" lower="-0.262" upper="0.611" velocity="0.0"/>
  </joint>
  <joint name="new_ragdoll__l_arm_joint" type="revolute">
    <parent link="new_ragdoll__upper_body"/>
    <child link="new_ragdoll__v_l_arm"/>
    <origin rpy="3.14  0    0" xyz="0.254    0       0.17526"/>
    <axis xyz="0       0.00159 -0.99999"/>
    <limit effort="0.0" lower="-3.094" upper="1.025" velocity="0.0"/>
  </joint>
  <joint name="new_ragdoll__L_arm_joint2" type="fixed">
    <parent link="new_ragdoll__v_l_arm"/>
    <child link="new_ragdoll__l_arm"/>
    <origin rpy="-3.14  0    0" xyz="0  0  0"/>
    <axis xyz="0  1  0"/>
    <limit effort="0.0" lower="-0.0" upper="0.0" velocity="0.0"/>
  </joint>
  <joint name="new_ragdoll__l_wrist_joint" type="revolute">
    <parent link="new_ragdoll__l_arm"/>
    <child link="new_ragdoll__l_wrist"/>
    <origin rpy="0  0  0" xyz="-0.28199  0       0.04953"/>
    <axis xyz="0  0  1"/>
    <limit effort="0.0" lower="-2.378" upper="0.0" velocity="0.0"/>
  </joint>
  <joint name="new_ragdoll__l_hand_joint" type="fixed">
    <parent link="new_ragdoll__l_wrist"/>
    <child link="new_ragdoll__l_hand"/>
    <origin rpy="0  0  0" xyz="-0.2515  0      0"/>
    <axis xyz="0  0  1"/>
    <limit effort="0.0" lower="0.0" upper="0.0" velocity="0.0"/>
  </joint>
  <joint name="new_ragdoll__neck_joint" type="fixed">
    <parent link="new_ragdoll__upper_body"/>
    <child link="new_ragdoll__neck"/>
    <origin rpy="0  0  0" xyz="0.35052  0       0"/>
    <axis xyz="0  0  1"/>
    <limit effort="0.0" lower="0.0" upper="0.0" velocity="0.0"/>
  </joint>
  <joint name="new_ragdoll__head_joint" type="fixed">
    <parent link="new_ragdoll__neck"/>
    <child link="new_ragdoll__head"/>
    <origin rpy="0  0  0" xyz="0.07238  0       0"/>
    <axis xyz="0  0  1"/>
    <limit effort="0.0" lower="0.0" upper="0.0" velocity="0.0"/>
  </joint>
  <joint name="new_ragdoll__R_arm_joint2" type="fixed">
    <parent link="new_ragdoll__v_r_arm"/>
    <child link="new_ragdoll__r_arm"/>
    <origin rpy="0  0  0" xyz="0  0  0"/>
    <axis xyz="0  1  0"/>
    <limit effort="0.0" lower="0.0" upper="0.0" velocity="0.0"/>
  </joint>
  <joint name="new_ragdoll__r_arm_joint" type="revolute">
    <parent link="new_ragdoll__upper_body"/>
    <child link="new_ragdoll__v_r_arm"/>
    <origin rpy="0  0  0" xyz="0.254    0      -0.17526"/>
    <axis xyz="0  0  1"/>
    <limit effort="0.0" lower="-3.094" upper="1.025" velocity="0.0"/>
  </joint>
  <joint name="new_ragdoll__r_wrist_joint" type="fixed">
    <parent link="new_ragdoll__r_arm"/>
    <child link="new_ragdoll__r_wrist"/>
    <origin rpy="0  0  0" xyz="-0.28199  0      -0.04953"/>
    <axis xyz="0  0  1"/>
    <limit effort="0.0" lower="0.0" upper="0.0" velocity="0.0"/>
  </joint>
  <joint name="new_ragdoll__r_hand_joint" type="fixed">
    <parent link="new_ragdoll__r_wrist"/>
    <child link="new_ragdoll__r_hand"/>
    <origin rpy="0  0  0" xyz="-0.2515  0      0"/>
    <axis xyz="0  0  1"/>
    <limit effort="0.0" lower="0.0" upper="0.0" velocity="0.0"/>
  </joint>
  <link name="new_ragdoll__lower_body">
    <inertial>
      <mass value="9.7"/>
      <origin rpy="0  0  0" xyz="0.0762  0      0"/>
      <inertia ixx="0.1116" ixy="0.000000" ixz="0.000000" iyy="0.1028" iyz="0.000000" izz="0.1298"/>
    </inertial>
    <collision name="new_ragdoll__lower_body_collision">
      <origin rpy="0   -1.57  0" xyz="0   0  10"/>
      <geometry>
        <mesh filename="package://ezgripper_driver/meshes/visual/SAKE_Finger.stl OR ezgripper_driver/meshes/visual/SAKE_Palm_Quad.stl OR ezgripper_driver/meshes/visual/SAKE_Palm_Dual.stl OR ezgripper_driver/meshes/collision/SAKE_Finger.stl OR ezgripper_driver/meshes/collision/SAKE_Palm_Quad.stl OR ezgripper_driver/meshes/collision/SAKE_Palm_Dual.stl OR ezgripper_driver/meshes/ezgripper_gen2/SAKE_Palm_Dual_Gen2.stl OR ezgripper_driver/meshes/ezgripper_gen2/SAKE_Finger_L1_Gen2.stl OR ezgripper_driver/meshes/ezgripper_gen2/SAKE_Finger_L2_Gen2.stl OR access_teleop/models/ragdoll/model.dae OR access_teleop/files/model_files/collada/cube_l.dae OR access_teleop/files/model_files/collada/ball.dae OR access_teleop/files/model_files/collada/cube_s.dae OR access_teleop/files/model_files/collada/cube_m.dae OR access_teleop/files/model_files/collada/stone.dae OR access_teleop/files/model_files/collada/cube_xl.dae OR access_teleop/files/model_files/collada/shelf.dae OR collada_web_server/fetch_description/meshes/gripper_link.dae OR collada_web_server/fetch_description/meshes/elbow_flex_link.dae OR collada_web_server/fetch_description/meshes/torso_fixed_link.dae OR collada_web_server/fetch_description/meshes/base_link.dae OR collada_web_server/fetch_description/meshes/shoulder_lift_link.dae OR collada_web_server/fetch_description/meshes/wrist_roll_link.dae OR collada_web_server/fetch_description/meshes/head_tilt_link.dae OR collada_web_server/fetch_description/meshes/upperarm_roll_link.dae OR collada_web_server/fetch_description/meshes/forearm_roll_link.dae OR collada_web_server/fetch_description/meshes/shoulder_pan_link.dae OR collada_web_server/fetch_description/meshes/torso_lift_link.dae OR collada_web_server/fetch_description/meshes/wrist_flex_link.dae OR collada_web_server/fetch_description/meshes/head_pan_link.dae" scale="1 1 1"/>
      </geometry>
    </collision>
    <visual name="new_ragdoll__lower_body_visual">
      <origin rpy="0   -1.57  0" xyz="0   0  10"/>
      <geometry>
        <mesh filename="package://ezgripper_driver/meshes/visual/SAKE_Finger.stl OR ezgripper_driver/meshes/visual/SAKE_Palm_Quad.stl OR ezgripper_driver/meshes/visual/SAKE_Palm_Dual.stl OR ezgripper_driver/meshes/collision/SAKE_Finger.stl OR ezgripper_driver/meshes/collision/SAKE_Palm_Quad.stl OR ezgripper_driver/meshes/collision/SAKE_Palm_Dual.stl OR ezgripper_driver/meshes/ezgripper_gen2/SAKE_Palm_Dual_Gen2.stl OR ezgripper_driver/meshes/ezgripper_gen2/SAKE_Finger_L1_Gen2.stl OR ezgripper_driver/meshes/ezgripper_gen2/SAKE_Finger_L2_Gen2.stl OR access_teleop/models/ragdoll/model.dae OR access_teleop/files/model_files/collada/cube_l.dae OR access_teleop/files/model_files/collada/ball.dae OR access_teleop/files/model_files/collada/cube_s.dae OR access_teleop/files/model_files/collada/cube_m.dae OR access_teleop/files/model_files/collada/stone.dae OR access_teleop/files/model_files/collada/cube_xl.dae OR access_teleop/files/model_files/collada/shelf.dae OR collada_web_server/fetch_description/meshes/gripper_link.dae OR collada_web_server/fetch_description/meshes/elbow_flex_link.dae OR collada_web_server/fetch_description/meshes/torso_fixed_link.dae OR collada_web_server/fetch_description/meshes/base_link.dae OR collada_web_server/fetch_description/meshes/shoulder_lift_link.dae OR collada_web_server/fetch_description/meshes/wrist_roll_link.dae OR collada_web_server/fetch_description/meshes/head_tilt_link.dae OR collada_web_server/fetch_description/meshes/upperarm_roll_link.dae OR collada_web_server/fetch_description/meshes/forearm_roll_link.dae OR collada_web_server/fetch_description/meshes/shoulder_pan_link.dae OR collada_web_server/fetch_description/meshes/torso_lift_link.dae OR collada_web_server/fetch_description/meshes/wrist_flex_link.dae OR collada_web_server/fetch_description/meshes/head_pan_link.dae" scale="1 1 1"/>
      </geometry>
    </visual>
  </link>
  <link name="new_ragdoll__l_thigh">
    <inertial>
      <mass value="12.3"/>
      <origin rpy="0  0  0" xyz="-0.21336  0       0"/>
      <inertia ixx="0.1652" ixy="0.000000" ixz="0.000000" iyy="0.1652" iyz="0.000000" izz="0.0452"/>
    </inertial>
    <collision name="new_ragdoll__l_thigh_collision">
      <origin rpy="0  0  0" xyz="-0.21336  0       0"/>
      <geometry>
        <mesh filename="package://ezgripper_driver/meshes/visual/SAKE_Finger.stl OR ezgripper_driver/meshes/visual/SAKE_Palm_Quad.stl OR ezgripper_driver/meshes/visual/SAKE_Palm_Dual.stl OR ezgripper_driver/meshes/collision/SAKE_Finger.stl OR ezgripper_driver/meshes/collision/SAKE_Palm_Quad.stl OR ezgripper_driver/meshes/collision/SAKE_Palm_Dual.stl OR ezgripper_driver/meshes/ezgripper_gen2/SAKE_Palm_Dual_Gen2.stl OR ezgripper_driver/meshes/ezgripper_gen2/SAKE_Finger_L1_Gen2.stl OR ezgripper_driver/meshes/ezgripper_gen2/SAKE_Finger_L2_Gen2.stl OR access_teleop/models/ragdoll/model.dae OR access_teleop/files/model_files/collada/cube_l.dae OR access_teleop/files/model_files/collada/ball.dae OR access_teleop/files/model_files/collada/cube_s.dae OR access_teleop/files/model_files/collada/cube_m.dae OR access_teleop/files/model_files/collada/stone.dae OR access_teleop/files/model_files/collada/cube_xl.dae OR access_teleop/files/model_files/collada/shelf.dae OR collada_web_server/fetch_description/meshes/gripper_link.dae OR collada_web_server/fetch_description/meshes/elbow_flex_link.dae OR collada_web_server/fetch_description/meshes/torso_fixed_link.dae OR collada_web_server/fetch_description/meshes/base_link.dae OR collada_web_server/fetch_description/meshes/shoulder_lift_link.dae OR collada_web_server/fetch_description/meshes/wrist_roll_link.dae OR collada_web_server/fetch_description/meshes/head_tilt_link.dae OR collada_web_server/fetch_description/meshes/upperarm_roll_link.dae OR collada_web_server/fetch_description/meshes/forearm_roll_link.dae OR collada_web_server/fetch_description/meshes/shoulder_pan_link.dae OR collada_web_server/fetch_description/meshes/torso_lift_link.dae OR collada_web_server/fetch_description/meshes/wrist_flex_link.dae OR collada_web_server/fetch_description/meshes/head_pan_link.dae" scale="1 1 1"/>
      </geometry>
    </collision>
    <visual name="new_ragdoll__l_thigh_visual">
      <origin rpy="0  0  0" xyz="-0.21336  0       0"/>
      <geometry>
        <mesh filename="package://ezgripper_driver/meshes/visual/SAKE_Finger.stl OR ezgripper_driver/meshes/visual/SAKE_Palm_Quad.stl OR ezgripper_driver/meshes/visual/SAKE_Palm_Dual.stl OR ezgripper_driver/meshes/collision/SAKE_Finger.stl OR ezgripper_driver/meshes/collision/SAKE_Palm_Quad.stl OR ezgripper_driver/meshes/collision/SAKE_Palm_Dual.stl OR ezgripper_driver/meshes/ezgripper_gen2/SAKE_Palm_Dual_Gen2.stl OR ezgripper_driver/meshes/ezgripper_gen2/SAKE_Finger_L1_Gen2.stl OR ezgripper_driver/meshes/ezgripper_gen2/SAKE_Finger_L2_Gen2.stl OR access_teleop/models/ragdoll/model.dae OR access_teleop/files/model_files/collada/cube_l.dae OR access_teleop/files/model_files/collada/ball.dae OR access_teleop/files/model_files/collada/cube_s.dae OR access_teleop/files/model_files/collada/cube_m.dae OR access_teleop/files/model_files/collada/stone.dae OR access_teleop/files/model_files/collada/cube_xl.dae OR access_teleop/files/model_files/collada/shelf.dae OR collada_web_server/fetch_description/meshes/gripper_link.dae OR collada_web_server/fetch_description/meshes/elbow_flex_link.dae OR collada_web_server/fetch_description/meshes/torso_fixed_link.dae OR collada_web_server/fetch_description/meshes/base_link.dae OR collada_web_server/fetch_description/meshes/shoulder_lift_link.dae OR collada_web_server/fetch_description/meshes/wrist_roll_link.dae OR collada_web_server/fetch_description/meshes/head_tilt_link.dae OR collada_web_server/fetch_description/meshes/upperarm_roll_link.dae OR collada_web_server/fetch_description/meshes/forearm_roll_link.dae OR collada_web_server/fetch_description/meshes/shoulder_pan_link.dae OR collada_web_server/fetch_description/meshes/torso_lift_link.dae OR collada_web_server/fetch_description/meshes/wrist_flex_link.dae OR collada_web_server/fetch_description/meshes/head_pan_link.dae" scale="1 1 1"/>
      </geometry>
    </visual>
  </link>
  <link name="new_ragdoll__l_shin">
    <inertial>
      <mass value="3.76"/>
      <origin rpy="0  0  0" xyz="-0.20701  0       0"/>
      <inertia ixx="0.0606" ixy="0.000000" ixz="0.000000" iyy="0.0606" iyz="0.000000" izz="0.0071"/>
    </inertial>
    <collision name="new_ragdoll__l_shin_collision">
      <origin rpy="0  0  0" xyz="-0.20701  0       0"/>
      <geometry>
        <mesh filename="package://ezgripper_driver/meshes/visual/SAKE_Finger.stl OR ezgripper_driver/meshes/visual/SAKE_Palm_Quad.stl OR ezgripper_driver/meshes/visual/SAKE_Palm_Dual.stl OR ezgripper_driver/meshes/collision/SAKE_Finger.stl OR ezgripper_driver/meshes/collision/SAKE_Palm_Quad.stl OR ezgripper_driver/meshes/collision/SAKE_Palm_Dual.stl OR ezgripper_driver/meshes/ezgripper_gen2/SAKE_Palm_Dual_Gen2.stl OR ezgripper_driver/meshes/ezgripper_gen2/SAKE_Finger_L1_Gen2.stl OR ezgripper_driver/meshes/ezgripper_gen2/SAKE_Finger_L2_Gen2.stl OR access_teleop/models/ragdoll/model.dae OR access_teleop/files/model_files/collada/cube_l.dae OR access_teleop/files/model_files/collada/ball.dae OR access_teleop/files/model_files/collada/cube_s.dae OR access_teleop/files/model_files/collada/cube_m.dae OR access_teleop/files/model_files/collada/stone.dae OR access_teleop/files/model_files/collada/cube_xl.dae OR access_teleop/files/model_files/collada/shelf.dae OR collada_web_server/fetch_description/meshes/gripper_link.dae OR collada_web_server/fetch_description/meshes/elbow_flex_link.dae OR collada_web_server/fetch_description/meshes/torso_fixed_link.dae OR collada_web_server/fetch_description/meshes/base_link.dae OR collada_web_server/fetch_description/meshes/shoulder_lift_link.dae OR collada_web_server/fetch_description/meshes/wrist_roll_link.dae OR collada_web_server/fetch_description/meshes/head_tilt_link.dae OR collada_web_server/fetch_description/meshes/upperarm_roll_link.dae OR collada_web_server/fetch_description/meshes/forearm_roll_link.dae OR collada_web_server/fetch_description/meshes/shoulder_pan_link.dae OR collada_web_server/fetch_description/meshes/torso_lift_link.dae OR collada_web_server/fetch_description/meshes/wrist_flex_link.dae OR collada_web_server/fetch_description/meshes/head_pan_link.dae" scale="1 1 1"/>
      </geometry>
    </collision>
    <visual name="new_ragdoll__l_shin_visual">
      <origin rpy="0  0  0" xyz="-0.20701  0       0"/>
      <geometry>
        <mesh filename="package://ezgripper_driver/meshes/visual/SAKE_Finger.stl OR ezgripper_driver/meshes/visual/SAKE_Palm_Quad.stl OR ezgripper_driver/meshes/visual/SAKE_Palm_Dual.stl OR ezgripper_driver/meshes/collision/SAKE_Finger.stl OR ezgripper_driver/meshes/collision/SAKE_Palm_Quad.stl OR ezgripper_driver/meshes/collision/SAKE_Palm_Dual.stl OR ezgripper_driver/meshes/ezgripper_gen2/SAKE_Palm_Dual_Gen2.stl OR ezgripper_driver/meshes/ezgripper_gen2/SAKE_Finger_L1_Gen2.stl OR ezgripper_driver/meshes/ezgripper_gen2/SAKE_Finger_L2_Gen2.stl OR access_teleop/models/ragdoll/model.dae OR access_teleop/files/model_files/collada/cube_l.dae OR access_teleop/files/model_files/collada/ball.dae OR access_teleop/files/model_files/collada/cube_s.dae OR access_teleop/files/model_files/collada/cube_m.dae OR access_teleop/files/model_files/collada/stone.dae OR access_teleop/files/model_files/collada/cube_xl.dae OR access_teleop/files/model_files/collada/shelf.dae OR collada_web_server/fetch_description/meshes/gripper_link.dae OR collada_web_server/fetch_description/meshes/elbow_flex_link.dae OR collada_web_server/fetch_description/meshes/torso_fixed_link.dae OR collada_web_server/fetch_description/meshes/base_link.dae OR collada_web_server/fetch_description/meshes/shoulder_lift_link.dae OR collada_web_server/fetch_description/meshes/wrist_roll_link.dae OR collada_web_server/fetch_description/meshes/head_tilt_link.dae OR collada_web_server/fetch_description/meshes/upperarm_roll_link.dae OR collada_web_server/fetch_description/meshes/forearm_roll_link.dae OR collada_web_server/fetch_description/meshes/shoulder_pan_link.dae OR collada_web_server/fetch_description/meshes/torso_lift_link.dae OR collada_web_server/fetch_description/meshes/wrist_flex_link.dae OR collada_web_server/fetch_description/meshes/head_pan_link.dae" scale="1 1 1"/>
      </geometry>
    </visual>
  </link>
  <link name="new_ragdoll__l_foot">
    <inertial>
      <mass value="1.19"/>
      <origin rpy="0  0  0" xyz="-0.05918  0.0508   0"/>
      <inertia ixx="0.0008" ixy="0.000000" ixz="0.000000" iyy="0.0044" iyz="0.000000" izz="0.0046"/>
    </inertial>
    <collision name="new_ragdoll__l_foot_geom">
      <origin rpy="0  0  0" xyz="0  0  0"/>
      <geometry>
        <mesh filename="package://ezgripper_driver/meshes/visual/SAKE_Finger.stl OR ezgripper_driver/meshes/visual/SAKE_Palm_Quad.stl OR ezgripper_driver/meshes/visual/SAKE_Palm_Dual.stl OR ezgripper_driver/meshes/collision/SAKE_Finger.stl OR ezgripper_driver/meshes/collision/SAKE_Palm_Quad.stl OR ezgripper_driver/meshes/collision/SAKE_Palm_Dual.stl OR ezgripper_driver/meshes/ezgripper_gen2/SAKE_Palm_Dual_Gen2.stl OR ezgripper_driver/meshes/ezgripper_gen2/SAKE_Finger_L1_Gen2.stl OR ezgripper_driver/meshes/ezgripper_gen2/SAKE_Finger_L2_Gen2.stl OR access_teleop/models/ragdoll/model.dae OR access_teleop/files/model_files/collada/cube_l.dae OR access_teleop/files/model_files/collada/ball.dae OR access_teleop/files/model_files/collada/cube_s.dae OR access_teleop/files/model_files/collada/cube_m.dae OR access_teleop/files/model_files/collada/stone.dae OR access_teleop/files/model_files/collada/cube_xl.dae OR access_teleop/files/model_files/collada/shelf.dae OR collada_web_server/fetch_description/meshes/gripper_link.dae OR collada_web_server/fetch_description/meshes/elbow_flex_link.dae OR collada_web_server/fetch_description/meshes/torso_fixed_link.dae OR collada_web_server/fetch_description/meshes/base_link.dae OR collada_web_server/fetch_description/meshes/shoulder_lift_link.dae OR collada_web_server/fetch_description/meshes/wrist_roll_link.dae OR collada_web_server/fetch_description/meshes/head_tilt_link.dae OR collada_web_server/fetch_description/meshes/upperarm_roll_link.dae OR collada_web_server/fetch_description/meshes/forearm_roll_link.dae OR collada_web_server/fetch_description/meshes/shoulder_pan_link.dae OR collada_web_server/fetch_description/meshes/torso_lift_link.dae OR collada_web_server/fetch_description/meshes/wrist_flex_link.dae OR collada_web_server/fetch_description/meshes/head_pan_link.dae" scale="1 1 1"/>
      </geometry>
    </collision>
    <visual name="new_ragdoll__l_foot_geom_visual">
      <origin rpy="0  0  0" xyz="0  0  0"/>
      <geometry>
        <mesh filename="package://ezgripper_driver/meshes/visual/SAKE_Finger.stl OR ezgripper_driver/meshes/visual/SAKE_Palm_Quad.stl OR ezgripper_driver/meshes/visual/SAKE_Palm_Dual.stl OR ezgripper_driver/meshes/collision/SAKE_Finger.stl OR ezgripper_driver/meshes/collision/SAKE_Palm_Quad.stl OR ezgripper_driver/meshes/collision/SAKE_Palm_Dual.stl OR ezgripper_driver/meshes/ezgripper_gen2/SAKE_Palm_Dual_Gen2.stl OR ezgripper_driver/meshes/ezgripper_gen2/SAKE_Finger_L1_Gen2.stl OR ezgripper_driver/meshes/ezgripper_gen2/SAKE_Finger_L2_Gen2.stl OR access_teleop/models/ragdoll/model.dae OR access_teleop/files/model_files/collada/cube_l.dae OR access_teleop/files/model_files/collada/ball.dae OR access_teleop/files/model_files/collada/cube_s.dae OR access_teleop/files/model_files/collada/cube_m.dae OR access_teleop/files/model_files/collada/stone.dae OR access_teleop/files/model_files/collada/cube_xl.dae OR access_teleop/files/model_files/collada/shelf.dae OR collada_web_server/fetch_description/meshes/gripper_link.dae OR collada_web_server/fetch_description/meshes/elbow_flex_link.dae OR collada_web_server/fetch_description/meshes/torso_fixed_link.dae OR collada_web_server/fetch_description/meshes/base_link.dae OR collada_web_server/fetch_description/meshes/shoulder_lift_link.dae OR collada_web_server/fetch_description/meshes/wrist_roll_link.dae OR collada_web_server/fetch_description/meshes/head_tilt_link.dae OR collada_web_server/fetch_description/meshes/upperarm_roll_link.dae OR collada_web_server/fetch_description/meshes/forearm_roll_link.dae OR collada_web_server/fetch_description/meshes/shoulder_pan_link.dae OR collada_web_server/fetch_description/meshes/torso_lift_link.dae OR collada_web_server/fetch_description/meshes/wrist_flex_link.dae OR collada_web_server/fetch_description/meshes/head_pan_link.dae" scale="1 1 1"/>
      </geometry>
    </visual>
  </link>
  <link name="new_ragdoll__r_thigh">
    <inertial>
      <mass value="12.3"/>
      <origin rpy="0  0  0" xyz="-0.21336  0       0"/>
      <inertia ixx="0.1652" ixy="0.000000" ixz="0.000000" iyy="0.1652" iyz="0.000000" izz="0.0452"/>
    </inertial>
    <collision name="new_ragdoll__r_thigh_collision">
      <origin rpy="0  0  0" xyz="-0.21336  0       0"/>
      <geometry>
        <mesh filename="package://ezgripper_driver/meshes/visual/SAKE_Finger.stl OR ezgripper_driver/meshes/visual/SAKE_Palm_Quad.stl OR ezgripper_driver/meshes/visual/SAKE_Palm_Dual.stl OR ezgripper_driver/meshes/collision/SAKE_Finger.stl OR ezgripper_driver/meshes/collision/SAKE_Palm_Quad.stl OR ezgripper_driver/meshes/collision/SAKE_Palm_Dual.stl OR ezgripper_driver/meshes/ezgripper_gen2/SAKE_Palm_Dual_Gen2.stl OR ezgripper_driver/meshes/ezgripper_gen2/SAKE_Finger_L1_Gen2.stl OR ezgripper_driver/meshes/ezgripper_gen2/SAKE_Finger_L2_Gen2.stl OR access_teleop/models/ragdoll/model.dae OR access_teleop/files/model_files/collada/cube_l.dae OR access_teleop/files/model_files/collada/ball.dae OR access_teleop/files/model_files/collada/cube_s.dae OR access_teleop/files/model_files/collada/cube_m.dae OR access_teleop/files/model_files/collada/stone.dae OR access_teleop/files/model_files/collada/cube_xl.dae OR access_teleop/files/model_files/collada/shelf.dae OR collada_web_server/fetch_description/meshes/gripper_link.dae OR collada_web_server/fetch_description/meshes/elbow_flex_link.dae OR collada_web_server/fetch_description/meshes/torso_fixed_link.dae OR collada_web_server/fetch_description/meshes/base_link.dae OR collada_web_server/fetch_description/meshes/shoulder_lift_link.dae OR collada_web_server/fetch_description/meshes/wrist_roll_link.dae OR collada_web_server/fetch_description/meshes/head_tilt_link.dae OR collada_web_server/fetch_description/meshes/upperarm_roll_link.dae OR collada_web_server/fetch_description/meshes/forearm_roll_link.dae OR collada_web_server/fetch_description/meshes/shoulder_pan_link.dae OR collada_web_server/fetch_description/meshes/torso_lift_link.dae OR collada_web_server/fetch_description/meshes/wrist_flex_link.dae OR collada_web_server/fetch_description/meshes/head_pan_link.dae" scale="1 1 1"/>
      </geometry>
    </collision>
    <visual name="new_ragdoll__r_thigh_visual">
      <origin rpy="0  0  0" xyz="-0.21336  0       0"/>
      <geometry>
        <mesh filename="package://ezgripper_driver/meshes/visual/SAKE_Finger.stl OR ezgripper_driver/meshes/visual/SAKE_Palm_Quad.stl OR ezgripper_driver/meshes/visual/SAKE_Palm_Dual.stl OR ezgripper_driver/meshes/collision/SAKE_Finger.stl OR ezgripper_driver/meshes/collision/SAKE_Palm_Quad.stl OR ezgripper_driver/meshes/collision/SAKE_Palm_Dual.stl OR ezgripper_driver/meshes/ezgripper_gen2/SAKE_Palm_Dual_Gen2.stl OR ezgripper_driver/meshes/ezgripper_gen2/SAKE_Finger_L1_Gen2.stl OR ezgripper_driver/meshes/ezgripper_gen2/SAKE_Finger_L2_Gen2.stl OR access_teleop/models/ragdoll/model.dae OR access_teleop/files/model_files/collada/cube_l.dae OR access_teleop/files/model_files/collada/ball.dae OR access_teleop/files/model_files/collada/cube_s.dae OR access_teleop/files/model_files/collada/cube_m.dae OR access_teleop/files/model_files/collada/stone.dae OR access_teleop/files/model_files/collada/cube_xl.dae OR access_teleop/files/model_files/collada/shelf.dae OR collada_web_server/fetch_description/meshes/gripper_link.dae OR collada_web_server/fetch_description/meshes/elbow_flex_link.dae OR collada_web_server/fetch_description/meshes/torso_fixed_link.dae OR collada_web_server/fetch_description/meshes/base_link.dae OR collada_web_server/fetch_description/meshes/shoulder_lift_link.dae OR collada_web_server/fetch_description/meshes/wrist_roll_link.dae OR collada_web_server/fetch_description/meshes/head_tilt_link.dae OR collada_web_server/fetch_description/meshes/upperarm_roll_link.dae OR collada_web_server/fetch_description/meshes/forearm_roll_link.dae OR collada_web_server/fetch_description/meshes/shoulder_pan_link.dae OR collada_web_server/fetch_description/meshes/torso_lift_link.dae OR collada_web_server/fetch_description/meshes/wrist_flex_link.dae OR collada_web_server/fetch_description/meshes/head_pan_link.dae" scale="1 1 1"/>
      </geometry>
    </visual>
  </link>
  <link name="new_ragdoll__r_shin">
    <inertial>
      <mass value="3.76"/>
      <origin rpy="0  0  0" xyz="-0.20701  0       0"/>
      <inertia ixx="0.0606" ixy="0.000000" ixz="0.000000" iyy="0.0606" iyz="0.000000" izz="0.0071"/>
    </inertial>
    <collision name="new_ragdoll__r_shin_collision">
      <origin rpy="0  0  0" xyz="-0.20701  0       0"/>
      <geometry>
        <mesh filename="package://ezgripper_driver/meshes/visual/SAKE_Finger.stl OR ezgripper_driver/meshes/visual/SAKE_Palm_Quad.stl OR ezgripper_driver/meshes/visual/SAKE_Palm_Dual.stl OR ezgripper_driver/meshes/collision/SAKE_Finger.stl OR ezgripper_driver/meshes/collision/SAKE_Palm_Quad.stl OR ezgripper_driver/meshes/collision/SAKE_Palm_Dual.stl OR ezgripper_driver/meshes/ezgripper_gen2/SAKE_Palm_Dual_Gen2.stl OR ezgripper_driver/meshes/ezgripper_gen2/SAKE_Finger_L1_Gen2.stl OR ezgripper_driver/meshes/ezgripper_gen2/SAKE_Finger_L2_Gen2.stl OR access_teleop/models/ragdoll/model.dae OR access_teleop/files/model_files/collada/cube_l.dae OR access_teleop/files/model_files/collada/ball.dae OR access_teleop/files/model_files/collada/cube_s.dae OR access_teleop/files/model_files/collada/cube_m.dae OR access_teleop/files/model_files/collada/stone.dae OR access_teleop/files/model_files/collada/cube_xl.dae OR access_teleop/files/model_files/collada/shelf.dae OR collada_web_server/fetch_description/meshes/gripper_link.dae OR collada_web_server/fetch_description/meshes/elbow_flex_link.dae OR collada_web_server/fetch_description/meshes/torso_fixed_link.dae OR collada_web_server/fetch_description/meshes/base_link.dae OR collada_web_server/fetch_description/meshes/shoulder_lift_link.dae OR collada_web_server/fetch_description/meshes/wrist_roll_link.dae OR collada_web_server/fetch_description/meshes/head_tilt_link.dae OR collada_web_server/fetch_description/meshes/upperarm_roll_link.dae OR collada_web_server/fetch_description/meshes/forearm_roll_link.dae OR collada_web_server/fetch_description/meshes/shoulder_pan_link.dae OR collada_web_server/fetch_description/meshes/torso_lift_link.dae OR collada_web_server/fetch_description/meshes/wrist_flex_link.dae OR collada_web_server/fetch_description/meshes/head_pan_link.dae" scale="1 1 1"/>
      </geometry>
    </collision>
    <visual name="new_ragdoll__r_shin_visual">
      <origin rpy="0  0  0" xyz="-0.20701  0       0"/>
      <geometry>
        <mesh filename="package://ezgripper_driver/meshes/visual/SAKE_Finger.stl OR ezgripper_driver/meshes/visual/SAKE_Palm_Quad.stl OR ezgripper_driver/meshes/visual/SAKE_Palm_Dual.stl OR ezgripper_driver/meshes/collision/SAKE_Finger.stl OR ezgripper_driver/meshes/collision/SAKE_Palm_Quad.stl OR ezgripper_driver/meshes/collision/SAKE_Palm_Dual.stl OR ezgripper_driver/meshes/ezgripper_gen2/SAKE_Palm_Dual_Gen2.stl OR ezgripper_driver/meshes/ezgripper_gen2/SAKE_Finger_L1_Gen2.stl OR ezgripper_driver/meshes/ezgripper_gen2/SAKE_Finger_L2_Gen2.stl OR access_teleop/models/ragdoll/model.dae OR access_teleop/files/model_files/collada/cube_l.dae OR access_teleop/files/model_files/collada/ball.dae OR access_teleop/files/model_files/collada/cube_s.dae OR access_teleop/files/model_files/collada/cube_m.dae OR access_teleop/files/model_files/collada/stone.dae OR access_teleop/files/model_files/collada/cube_xl.dae OR access_teleop/files/model_files/collada/shelf.dae OR collada_web_server/fetch_description/meshes/gripper_link.dae OR collada_web_server/fetch_description/meshes/elbow_flex_link.dae OR collada_web_server/fetch_description/meshes/torso_fixed_link.dae OR collada_web_server/fetch_description/meshes/base_link.dae OR collada_web_server/fetch_description/meshes/shoulder_lift_link.dae OR collada_web_server/fetch_description/meshes/wrist_roll_link.dae OR collada_web_server/fetch_description/meshes/head_tilt_link.dae OR collada_web_server/fetch_description/meshes/upperarm_roll_link.dae OR collada_web_server/fetch_description/meshes/forearm_roll_link.dae OR collada_web_server/fetch_description/meshes/shoulder_pan_link.dae OR collada_web_server/fetch_description/meshes/torso_lift_link.dae OR collada_web_server/fetch_description/meshes/wrist_flex_link.dae OR collada_web_server/fetch_description/meshes/head_pan_link.dae" scale="1 1 1"/>
      </geometry>
    </visual>
  </link>
  <link name="new_ragdoll__r_foot">
    <inertial>
      <mass value="1.19"/>
      <origin rpy="0  0  0" xyz="-0.05918  0.0508   0"/>
      <inertia ixx="0.0008" ixy="0.000000" ixz="0.000000" iyy="0.0044" iyz="0.000000" izz="0.0046"/>
    </inertial>
    <collision name="new_ragdoll__r_foot_collision">
      <origin rpy="0  0  0" xyz="0  0  0"/>
      <geometry>
        <mesh filename="package://ezgripper_driver/meshes/visual/SAKE_Finger.stl OR ezgripper_driver/meshes/visual/SAKE_Palm_Quad.stl OR ezgripper_driver/meshes/visual/SAKE_Palm_Dual.stl OR ezgripper_driver/meshes/collision/SAKE_Finger.stl OR ezgripper_driver/meshes/collision/SAKE_Palm_Quad.stl OR ezgripper_driver/meshes/collision/SAKE_Palm_Dual.stl OR ezgripper_driver/meshes/ezgripper_gen2/SAKE_Palm_Dual_Gen2.stl OR ezgripper_driver/meshes/ezgripper_gen2/SAKE_Finger_L1_Gen2.stl OR ezgripper_driver/meshes/ezgripper_gen2/SAKE_Finger_L2_Gen2.stl OR access_teleop/models/ragdoll/model.dae OR access_teleop/files/model_files/collada/cube_l.dae OR access_teleop/files/model_files/collada/ball.dae OR access_teleop/files/model_files/collada/cube_s.dae OR access_teleop/files/model_files/collada/cube_m.dae OR access_teleop/files/model_files/collada/stone.dae OR access_teleop/files/model_files/collada/cube_xl.dae OR access_teleop/files/model_files/collada/shelf.dae OR collada_web_server/fetch_description/meshes/gripper_link.dae OR collada_web_server/fetch_description/meshes/elbow_flex_link.dae OR collada_web_server/fetch_description/meshes/torso_fixed_link.dae OR collada_web_server/fetch_description/meshes/base_link.dae OR collada_web_server/fetch_description/meshes/shoulder_lift_link.dae OR collada_web_server/fetch_description/meshes/wrist_roll_link.dae OR collada_web_server/fetch_description/meshes/head_tilt_link.dae OR collada_web_server/fetch_description/meshes/upperarm_roll_link.dae OR collada_web_server/fetch_description/meshes/forearm_roll_link.dae OR collada_web_server/fetch_description/meshes/shoulder_pan_link.dae OR collada_web_server/fetch_description/meshes/torso_lift_link.dae OR collada_web_server/fetch_description/meshes/wrist_flex_link.dae OR collada_web_server/fetch_description/meshes/head_pan_link.dae" scale="1 1 1"/>
      </geometry>
    </collision>
    <visual name="new_ragdoll__r_foot_visual">
      <origin rpy="0  0  0" xyz="0  0  0"/>
      <geometry>
        <mesh filename="package://ezgripper_driver/meshes/visual/SAKE_Finger.stl OR ezgripper_driver/meshes/visual/SAKE_Palm_Quad.stl OR ezgripper_driver/meshes/visual/SAKE_Palm_Dual.stl OR ezgripper_driver/meshes/collision/SAKE_Finger.stl OR ezgripper_driver/meshes/collision/SAKE_Palm_Quad.stl OR ezgripper_driver/meshes/collision/SAKE_Palm_Dual.stl OR ezgripper_driver/meshes/ezgripper_gen2/SAKE_Palm_Dual_Gen2.stl OR ezgripper_driver/meshes/ezgripper_gen2/SAKE_Finger_L1_Gen2.stl OR ezgripper_driver/meshes/ezgripper_gen2/SAKE_Finger_L2_Gen2.stl OR access_teleop/models/ragdoll/model.dae OR access_teleop/files/model_files/collada/cube_l.dae OR access_teleop/files/model_files/collada/ball.dae OR access_teleop/files/model_files/collada/cube_s.dae OR access_teleop/files/model_files/collada/cube_m.dae OR access_teleop/files/model_files/collada/stone.dae OR access_teleop/files/model_files/collada/cube_xl.dae OR access_teleop/files/model_files/collada/shelf.dae OR collada_web_server/fetch_description/meshes/gripper_link.dae OR collada_web_server/fetch_description/meshes/elbow_flex_link.dae OR collada_web_server/fetch_description/meshes/torso_fixed_link.dae OR collada_web_server/fetch_description/meshes/base_link.dae OR collada_web_server/fetch_description/meshes/shoulder_lift_link.dae OR collada_web_server/fetch_description/meshes/wrist_roll_link.dae OR collada_web_server/fetch_description/meshes/head_tilt_link.dae OR collada_web_server/fetch_description/meshes/upperarm_roll_link.dae OR collada_web_server/fetch_description/meshes/forearm_roll_link.dae OR collada_web_server/fetch_description/meshes/shoulder_pan_link.dae OR collada_web_server/fetch_description/meshes/torso_lift_link.dae OR collada_web_server/fetch_description/meshes/wrist_flex_link.dae OR collada_web_server/fetch_description/meshes/head_pan_link.dae" scale="1 1 1"/>
      </geometry>
    </visual>
  </link>
  <link name="new_ragdoll__middle_body">
    <inertial>
      <mass value="14.2"/>
      <origin rpy="0  0  0" xyz="0.17653  0       0"/>
      <inertia ixx="0.1116" ixy="0.000000" ixz="0.000000" iyy="0.1028" iyz="0.000000" izz="0.1298"/>
    </inertial>
    <collision name="new_ragdoll__middle_body_collision">
      <origin rpy="0  0  0" xyz="0  0  0"/>
      <geometry>
        <mesh filename="package://ezgripper_driver/meshes/visual/SAKE_Finger.stl OR ezgripper_driver/meshes/visual/SAKE_Palm_Quad.stl OR ezgripper_driver/meshes/visual/SAKE_Palm_Dual.stl OR ezgripper_driver/meshes/collision/SAKE_Finger.stl OR ezgripper_driver/meshes/collision/SAKE_Palm_Quad.stl OR ezgripper_driver/meshes/collision/SAKE_Palm_Dual.stl OR ezgripper_driver/meshes/ezgripper_gen2/SAKE_Palm_Dual_Gen2.stl OR ezgripper_driver/meshes/ezgripper_gen2/SAKE_Finger_L1_Gen2.stl OR ezgripper_driver/meshes/ezgripper_gen2/SAKE_Finger_L2_Gen2.stl OR access_teleop/models/ragdoll/model.dae OR access_teleop/files/model_files/collada/cube_l.dae OR access_teleop/files/model_files/collada/ball.dae OR access_teleop/files/model_files/collada/cube_s.dae OR access_teleop/files/model_files/collada/cube_m.dae OR access_teleop/files/model_files/collada/stone.dae OR access_teleop/files/model_files/collada/cube_xl.dae OR access_teleop/files/model_files/collada/shelf.dae OR collada_web_server/fetch_description/meshes/gripper_link.dae OR collada_web_server/fetch_description/meshes/elbow_flex_link.dae OR collada_web_server/fetch_description/meshes/torso_fixed_link.dae OR collada_web_server/fetch_description/meshes/base_link.dae OR collada_web_server/fetch_description/meshes/shoulder_lift_link.dae OR collada_web_server/fetch_description/meshes/wrist_roll_link.dae OR collada_web_server/fetch_description/meshes/head_tilt_link.dae OR collada_web_server/fetch_description/meshes/upperarm_roll_link.dae OR collada_web_server/fetch_description/meshes/forearm_roll_link.dae OR collada_web_server/fetch_description/meshes/shoulder_pan_link.dae OR collada_web_server/fetch_description/meshes/torso_lift_link.dae OR collada_web_server/fetch_description/meshes/wrist_flex_link.dae OR collada_web_server/fetch_description/meshes/head_pan_link.dae" scale="1 1 1"/>
      </geometry>
    </collision>
    <visual name="new_ragdoll__middle_body_visual">
      <origin rpy="0  0  0" xyz="0  0  0"/>
      <geometry>
        <mesh filename="package://ezgripper_driver/meshes/visual/SAKE_Finger.stl OR ezgripper_driver/meshes/visual/SAKE_Palm_Quad.stl OR ezgripper_driver/meshes/visual/SAKE_Palm_Dual.stl OR ezgripper_driver/meshes/collision/SAKE_Finger.stl OR ezgripper_driver/meshes/collision/SAKE_Palm_Quad.stl OR ezgripper_driver/meshes/collision/SAKE_Palm_Dual.stl OR ezgripper_driver/meshes/ezgripper_gen2/SAKE_Palm_Dual_Gen2.stl OR ezgripper_driver/meshes/ezgripper_gen2/SAKE_Finger_L1_Gen2.stl OR ezgripper_driver/meshes/ezgripper_gen2/SAKE_Finger_L2_Gen2.stl OR access_teleop/models/ragdoll/model.dae OR access_teleop/files/model_files/collada/cube_l.dae OR access_teleop/files/model_files/collada/ball.dae OR access_teleop/files/model_files/collada/cube_s.dae OR access_teleop/files/model_files/collada/cube_m.dae OR access_teleop/files/model_files/collada/stone.dae OR access_teleop/files/model_files/collada/cube_xl.dae OR access_teleop/files/model_files/collada/shelf.dae OR collada_web_server/fetch_description/meshes/gripper_link.dae OR collada_web_server/fetch_description/meshes/elbow_flex_link.dae OR collada_web_server/fetch_description/meshes/torso_fixed_link.dae OR collada_web_server/fetch_description/meshes/base_link.dae OR collada_web_server/fetch_description/meshes/shoulder_lift_link.dae OR collada_web_server/fetch_description/meshes/wrist_roll_link.dae OR collada_web_server/fetch_description/meshes/head_tilt_link.dae OR collada_web_server/fetch_description/meshes/upperarm_roll_link.dae OR collada_web_server/fetch_description/meshes/forearm_roll_link.dae OR collada_web_server/fetch_description/meshes/shoulder_pan_link.dae OR collada_web_server/fetch_description/meshes/torso_lift_link.dae OR collada_web_server/fetch_description/meshes/wrist_flex_link.dae OR collada_web_server/fetch_description/meshes/head_pan_link.dae" scale="1 1 1"/>
      </geometry>
    </visual>
  </link>
  <link name="new_ragdoll__upper_body">
    <inertial>
      <mass value="12.82"/>
      <origin rpy="0  0  0" xyz="0.1778  0      0"/>
      <inertia ixx="0.1116" ixy="0.000000" ixz="0.000000" iyy="0.1028" iyz="0.000000" izz="0.1298"/>
    </inertial>
    <collision name="new_ragdoll__upper_body_collision">
      <origin rpy="0  0  0" xyz="0  0  0"/>
      <geometry>
        <mesh filename="package://ezgripper_driver/meshes/visual/SAKE_Finger.stl OR ezgripper_driver/meshes/visual/SAKE_Palm_Quad.stl OR ezgripper_driver/meshes/visual/SAKE_Palm_Dual.stl OR ezgripper_driver/meshes/collision/SAKE_Finger.stl OR ezgripper_driver/meshes/collision/SAKE_Palm_Quad.stl OR ezgripper_driver/meshes/collision/SAKE_Palm_Dual.stl OR ezgripper_driver/meshes/ezgripper_gen2/SAKE_Palm_Dual_Gen2.stl OR ezgripper_driver/meshes/ezgripper_gen2/SAKE_Finger_L1_Gen2.stl OR ezgripper_driver/meshes/ezgripper_gen2/SAKE_Finger_L2_Gen2.stl OR access_teleop/models/ragdoll/model.dae OR access_teleop/files/model_files/collada/cube_l.dae OR access_teleop/files/model_files/collada/ball.dae OR access_teleop/files/model_files/collada/cube_s.dae OR access_teleop/files/model_files/collada/cube_m.dae OR access_teleop/files/model_files/collada/stone.dae OR access_teleop/files/model_files/collada/cube_xl.dae OR access_teleop/files/model_files/collada/shelf.dae OR collada_web_server/fetch_description/meshes/gripper_link.dae OR collada_web_server/fetch_description/meshes/elbow_flex_link.dae OR collada_web_server/fetch_description/meshes/torso_fixed_link.dae OR collada_web_server/fetch_description/meshes/base_link.dae OR collada_web_server/fetch_description/meshes/shoulder_lift_link.dae OR collada_web_server/fetch_description/meshes/wrist_roll_link.dae OR collada_web_server/fetch_description/meshes/head_tilt_link.dae OR collada_web_server/fetch_description/meshes/upperarm_roll_link.dae OR collada_web_server/fetch_description/meshes/forearm_roll_link.dae OR collada_web_server/fetch_description/meshes/shoulder_pan_link.dae OR collada_web_server/fetch_description/meshes/torso_lift_link.dae OR collada_web_server/fetch_description/meshes/wrist_flex_link.dae OR collada_web_server/fetch_description/meshes/head_pan_link.dae" scale="1 1 1"/>
      </geometry>
    </collision>
    <visual name="new_ragdoll__upper_body_visual">
      <origin rpy="0  0  0" xyz="0  0  0"/>
      <geometry>
        <mesh filename="package://ezgripper_driver/meshes/visual/SAKE_Finger.stl OR ezgripper_driver/meshes/visual/SAKE_Palm_Quad.stl OR ezgripper_driver/meshes/visual/SAKE_Palm_Dual.stl OR ezgripper_driver/meshes/collision/SAKE_Finger.stl OR ezgripper_driver/meshes/collision/SAKE_Palm_Quad.stl OR ezgripper_driver/meshes/collision/SAKE_Palm_Dual.stl OR ezgripper_driver/meshes/ezgripper_gen2/SAKE_Palm_Dual_Gen2.stl OR ezgripper_driver/meshes/ezgripper_gen2/SAKE_Finger_L1_Gen2.stl OR ezgripper_driver/meshes/ezgripper_gen2/SAKE_Finger_L2_Gen2.stl OR access_teleop/models/ragdoll/model.dae OR access_teleop/files/model_files/collada/cube_l.dae OR access_teleop/files/model_files/collada/ball.dae OR access_teleop/files/model_files/collada/cube_s.dae OR access_teleop/files/model_files/collada/cube_m.dae OR access_teleop/files/model_files/collada/stone.dae OR access_teleop/files/model_files/collada/cube_xl.dae OR access_teleop/files/model_files/collada/shelf.dae OR collada_web_server/fetch_description/meshes/gripper_link.dae OR collada_web_server/fetch_description/meshes/elbow_flex_link.dae OR collada_web_server/fetch_description/meshes/torso_fixed_link.dae OR collada_web_server/fetch_description/meshes/base_link.dae OR collada_web_server/fetch_description/meshes/shoulder_lift_link.dae OR collada_web_server/fetch_description/meshes/wrist_roll_link.dae OR collada_web_server/fetch_description/meshes/head_tilt_link.dae OR collada_web_server/fetch_description/meshes/upperarm_roll_link.dae OR collada_web_server/fetch_description/meshes/forearm_roll_link.dae OR collada_web_server/fetch_description/meshes/shoulder_pan_link.dae OR collada_web_server/fetch_description/meshes/torso_lift_link.dae OR collada_web_server/fetch_description/meshes/wrist_flex_link.dae OR collada_web_server/fetch_description/meshes/head_pan_link.dae" scale="1 1 1"/>
      </geometry>
    </visual>
  </link>
  <link name="new_ragdoll__l_arm">
    <inertial>
      <mass value="2.35"/>
      <origin rpy="0  0  0" xyz="-0.14097  0       0.04953"/>
      <inertia ixx="0.0141" ixy="0.000000" ixz="0.000000" iyy="0.0141" iyz="0.000000" izz="0.0029"/>
    </inertial>
    <collision name="new_ragdoll__l_arm_collision">
      <origin rpy="3.14  0    0" xyz="-0.14097  0       0.04953"/>
      <geometry>
        <mesh filename="package://ezgripper_driver/meshes/visual/SAKE_Finger.stl OR ezgripper_driver/meshes/visual/SAKE_Palm_Quad.stl OR ezgripper_driver/meshes/visual/SAKE_Palm_Dual.stl OR ezgripper_driver/meshes/collision/SAKE_Finger.stl OR ezgripper_driver/meshes/collision/SAKE_Palm_Quad.stl OR ezgripper_driver/meshes/collision/SAKE_Palm_Dual.stl OR ezgripper_driver/meshes/ezgripper_gen2/SAKE_Palm_Dual_Gen2.stl OR ezgripper_driver/meshes/ezgripper_gen2/SAKE_Finger_L1_Gen2.stl OR ezgripper_driver/meshes/ezgripper_gen2/SAKE_Finger_L2_Gen2.stl OR access_teleop/models/ragdoll/model.dae OR access_teleop/files/model_files/collada/cube_l.dae OR access_teleop/files/model_files/collada/ball.dae OR access_teleop/files/model_files/collada/cube_s.dae OR access_teleop/files/model_files/collada/cube_m.dae OR access_teleop/files/model_files/collada/stone.dae OR access_teleop/files/model_files/collada/cube_xl.dae OR access_teleop/files/model_files/collada/shelf.dae OR collada_web_server/fetch_description/meshes/gripper_link.dae OR collada_web_server/fetch_description/meshes/elbow_flex_link.dae OR collada_web_server/fetch_description/meshes/torso_fixed_link.dae OR collada_web_server/fetch_description/meshes/base_link.dae OR collada_web_server/fetch_description/meshes/shoulder_lift_link.dae OR collada_web_server/fetch_description/meshes/wrist_roll_link.dae OR collada_web_server/fetch_description/meshes/head_tilt_link.dae OR collada_web_server/fetch_description/meshes/upperarm_roll_link.dae OR collada_web_server/fetch_description/meshes/forearm_roll_link.dae OR collada_web_server/fetch_description/meshes/shoulder_pan_link.dae OR collada_web_server/fetch_description/meshes/torso_lift_link.dae OR collada_web_server/fetch_description/meshes/wrist_flex_link.dae OR collada_web_server/fetch_description/meshes/head_pan_link.dae" scale="1 1 1"/>
      </geometry>
    </collision>
    <visual name="new_ragdoll__l_arm_visual">
      <origin rpy="3.14  0    0" xyz="-0.14097  0       0.04953"/>
      <geometry>
        <mesh filename="package://ezgripper_driver/meshes/visual/SAKE_Finger.stl OR ezgripper_driver/meshes/visual/SAKE_Palm_Quad.stl OR ezgripper_driver/meshes/visual/SAKE_Palm_Dual.stl OR ezgripper_driver/meshes/collision/SAKE_Finger.stl OR ezgripper_driver/meshes/collision/SAKE_Palm_Quad.stl OR ezgripper_driver/meshes/collision/SAKE_Palm_Dual.stl OR ezgripper_driver/meshes/ezgripper_gen2/SAKE_Palm_Dual_Gen2.stl OR ezgripper_driver/meshes/ezgripper_gen2/SAKE_Finger_L1_Gen2.stl OR ezgripper_driver/meshes/ezgripper_gen2/SAKE_Finger_L2_Gen2.stl OR access_teleop/models/ragdoll/model.dae OR access_teleop/files/model_files/collada/cube_l.dae OR access_teleop/files/model_files/collada/ball.dae OR access_teleop/files/model_files/collada/cube_s.dae OR access_teleop/files/model_files/collada/cube_m.dae OR access_teleop/files/model_files/collada/stone.dae OR access_teleop/files/model_files/collada/cube_xl.dae OR access_teleop/files/model_files/collada/shelf.dae OR collada_web_server/fetch_description/meshes/gripper_link.dae OR collada_web_server/fetch_description/meshes/elbow_flex_link.dae OR collada_web_server/fetch_description/meshes/torso_fixed_link.dae OR collada_web_server/fetch_description/meshes/base_link.dae OR collada_web_server/fetch_description/meshes/shoulder_lift_link.dae OR collada_web_server/fetch_description/meshes/wrist_roll_link.dae OR collada_web_server/fetch_description/meshes/head_tilt_link.dae OR collada_web_server/fetch_description/meshes/upperarm_roll_link.dae OR collada_web_server/fetch_description/meshes/forearm_roll_link.dae OR collada_web_server/fetch_description/meshes/shoulder_pan_link.dae OR collada_web_server/fetch_description/meshes/torso_lift_link.dae OR collada_web_server/fetch_description/meshes/wrist_flex_link.dae OR collada_web_server/fetch_description/meshes/head_pan_link.dae" scale="1 1 1"/>
      </geometry>
    </visual>
  </link>
  <link name="new_ragdoll__l_wrist">
    <inertial>
      <mass value="1.4"/>
      <origin rpy="0  0  0" xyz="-0.1257  0      0"/>
      <inertia ixx="0.009" ixy="0.000000" ixz="0.000000" iyy="0.009" iyz="0.000000" izz="0.0014"/>
    </inertial>
    <collision name="new_ragdoll__l_wrist_collision">
      <origin rpy="3.14  0    0" xyz="-0.1257  0      0"/>
      <geometry>
        <mesh filename="package://ezgripper_driver/meshes/visual/SAKE_Finger.stl OR ezgripper_driver/meshes/visual/SAKE_Palm_Quad.stl OR ezgripper_driver/meshes/visual/SAKE_Palm_Dual.stl OR ezgripper_driver/meshes/collision/SAKE_Finger.stl OR ezgripper_driver/meshes/collision/SAKE_Palm_Quad.stl OR ezgripper_driver/meshes/collision/SAKE_Palm_Dual.stl OR ezgripper_driver/meshes/ezgripper_gen2/SAKE_Palm_Dual_Gen2.stl OR ezgripper_driver/meshes/ezgripper_gen2/SAKE_Finger_L1_Gen2.stl OR ezgripper_driver/meshes/ezgripper_gen2/SAKE_Finger_L2_Gen2.stl OR access_teleop/models/ragdoll/model.dae OR access_teleop/files/model_files/collada/cube_l.dae OR access_teleop/files/model_files/collada/ball.dae OR access_teleop/files/model_files/collada/cube_s.dae OR access_teleop/files/model_files/collada/cube_m.dae OR access_teleop/files/model_files/collada/stone.dae OR access_teleop/files/model_files/collada/cube_xl.dae OR access_teleop/files/model_files/collada/shelf.dae OR collada_web_server/fetch_description/meshes/gripper_link.dae OR collada_web_server/fetch_description/meshes/elbow_flex_link.dae OR collada_web_server/fetch_description/meshes/torso_fixed_link.dae OR collada_web_server/fetch_description/meshes/base_link.dae OR collada_web_server/fetch_description/meshes/shoulder_lift_link.dae OR collada_web_server/fetch_description/meshes/wrist_roll_link.dae OR collada_web_server/fetch_description/meshes/head_tilt_link.dae OR collada_web_server/fetch_description/meshes/upperarm_roll_link.dae OR collada_web_server/fetch_description/meshes/forearm_roll_link.dae OR collada_web_server/fetch_description/meshes/shoulder_pan_link.dae OR collada_web_server/fetch_description/meshes/torso_lift_link.dae OR collada_web_server/fetch_description/meshes/wrist_flex_link.dae OR collada_web_server/fetch_description/meshes/head_pan_link.dae" scale="1 1 1"/>
      </geometry>
    </collision>
    <visual name="new_ragdoll__l_wrist_visual">
      <origin rpy="3.14  0    0" xyz="-0.1257  0      0"/>
      <geometry>
        <mesh filename="package://ezgripper_driver/meshes/visual/SAKE_Finger.stl OR ezgripper_driver/meshes/visual/SAKE_Palm_Quad.stl OR ezgripper_driver/meshes/visual/SAKE_Palm_Dual.stl OR ezgripper_driver/meshes/collision/SAKE_Finger.stl OR ezgripper_driver/meshes/collision/SAKE_Palm_Quad.stl OR ezgripper_driver/meshes/collision/SAKE_Palm_Dual.stl OR ezgripper_driver/meshes/ezgripper_gen2/SAKE_Palm_Dual_Gen2.stl OR ezgripper_driver/meshes/ezgripper_gen2/SAKE_Finger_L1_Gen2.stl OR ezgripper_driver/meshes/ezgripper_gen2/SAKE_Finger_L2_Gen2.stl OR access_teleop/models/ragdoll/model.dae OR access_teleop/files/model_files/collada/cube_l.dae OR access_teleop/files/model_files/collada/ball.dae OR access_teleop/files/model_files/collada/cube_s.dae OR access_teleop/files/model_files/collada/cube_m.dae OR access_teleop/files/model_files/collada/stone.dae OR access_teleop/files/model_files/collada/cube_xl.dae OR access_teleop/files/model_files/collada/shelf.dae OR collada_web_server/fetch_description/meshes/gripper_link.dae OR collada_web_server/fetch_description/meshes/elbow_flex_link.dae OR collada_web_server/fetch_description/meshes/torso_fixed_link.dae OR collada_web_server/fetch_description/meshes/base_link.dae OR collada_web_server/fetch_description/meshes/shoulder_lift_link.dae OR collada_web_server/fetch_description/meshes/wrist_roll_link.dae OR collada_web_server/fetch_description/meshes/head_tilt_link.dae OR collada_web_server/fetch_description/meshes/upperarm_roll_link.dae OR collada_web_server/fetch_description/meshes/forearm_roll_link.dae OR collada_web_server/fetch_description/meshes/shoulder_pan_link.dae OR collada_web_server/fetch_description/meshes/torso_lift_link.dae OR collada_web_server/fetch_description/meshes/wrist_flex_link.dae OR collada_web_server/fetch_description/meshes/head_pan_link.dae" scale="1 1 1"/>
      </geometry>
    </visual>
  </link>
  <link name="new_ragdoll__l_hand">
    <inertial>
      <mass value="0.5"/>
      <origin rpy="0  0  0" xyz="-0.105  0     0"/>
      <inertia ixx="0.0013" ixy="0.000000" ixz="0.000000" iyy="0.0011" iyz="0.000000" izz="0.0004"/>
    </inertial>
    <collision name="new_ragdoll__l_hand_collision">
      <origin rpy="3.14  0    0" xyz="0  0  0"/>
      <geometry>
        <mesh filename="package://ezgripper_driver/meshes/visual/SAKE_Finger.stl OR ezgripper_driver/meshes/visual/SAKE_Palm_Quad.stl OR ezgripper_driver/meshes/visual/SAKE_Palm_Dual.stl OR ezgripper_driver/meshes/collision/SAKE_Finger.stl OR ezgripper_driver/meshes/collision/SAKE_Palm_Quad.stl OR ezgripper_driver/meshes/collision/SAKE_Palm_Dual.stl OR ezgripper_driver/meshes/ezgripper_gen2/SAKE_Palm_Dual_Gen2.stl OR ezgripper_driver/meshes/ezgripper_gen2/SAKE_Finger_L1_Gen2.stl OR ezgripper_driver/meshes/ezgripper_gen2/SAKE_Finger_L2_Gen2.stl OR access_teleop/models/ragdoll/model.dae OR access_teleop/files/model_files/collada/cube_l.dae OR access_teleop/files/model_files/collada/ball.dae OR access_teleop/files/model_files/collada/cube_s.dae OR access_teleop/files/model_files/collada/cube_m.dae OR access_teleop/files/model_files/collada/stone.dae OR access_teleop/files/model_files/collada/cube_xl.dae OR access_teleop/files/model_files/collada/shelf.dae OR collada_web_server/fetch_description/meshes/gripper_link.dae OR collada_web_server/fetch_description/meshes/elbow_flex_link.dae OR collada_web_server/fetch_description/meshes/torso_fixed_link.dae OR collada_web_server/fetch_description/meshes/base_link.dae OR collada_web_server/fetch_description/meshes/shoulder_lift_link.dae OR collada_web_server/fetch_description/meshes/wrist_roll_link.dae OR collada_web_server/fetch_description/meshes/head_tilt_link.dae OR collada_web_server/fetch_description/meshes/upperarm_roll_link.dae OR collada_web_server/fetch_description/meshes/forearm_roll_link.dae OR collada_web_server/fetch_description/meshes/shoulder_pan_link.dae OR collada_web_server/fetch_description/meshes/torso_lift_link.dae OR collada_web_server/fetch_description/meshes/wrist_flex_link.dae OR collada_web_server/fetch_description/meshes/head_pan_link.dae" scale="1 1 1"/>
      </geometry>
    </collision>
    <visual name="new_ragdoll__l_hand_visual">
      <origin rpy="3.14  0    0" xyz="0  0  0"/>
      <geometry>
        <mesh filename="package://ezgripper_driver/meshes/visual/SAKE_Finger.stl OR ezgripper_driver/meshes/visual/SAKE_Palm_Quad.stl OR ezgripper_driver/meshes/visual/SAKE_Palm_Dual.stl OR ezgripper_driver/meshes/collision/SAKE_Finger.stl OR ezgripper_driver/meshes/collision/SAKE_Palm_Quad.stl OR ezgripper_driver/meshes/collision/SAKE_Palm_Dual.stl OR ezgripper_driver/meshes/ezgripper_gen2/SAKE_Palm_Dual_Gen2.stl OR ezgripper_driver/meshes/ezgripper_gen2/SAKE_Finger_L1_Gen2.stl OR ezgripper_driver/meshes/ezgripper_gen2/SAKE_Finger_L2_Gen2.stl OR access_teleop/models/ragdoll/model.dae OR access_teleop/files/model_files/collada/cube_l.dae OR access_teleop/files/model_files/collada/ball.dae OR access_teleop/files/model_files/collada/cube_s.dae OR access_teleop/files/model_files/collada/cube_m.dae OR access_teleop/files/model_files/collada/stone.dae OR access_teleop/files/model_files/collada/cube_xl.dae OR access_teleop/files/model_files/collada/shelf.dae OR collada_web_server/fetch_description/meshes/gripper_link.dae OR collada_web_server/fetch_description/meshes/elbow_flex_link.dae OR collada_web_server/fetch_description/meshes/torso_fixed_link.dae OR collada_web_server/fetch_description/meshes/base_link.dae OR collada_web_server/fetch_description/meshes/shoulder_lift_link.dae OR collada_web_server/fetch_description/meshes/wrist_roll_link.dae OR collada_web_server/fetch_description/meshes/head_tilt_link.dae OR collada_web_server/fetch_description/meshes/upperarm_roll_link.dae OR collada_web_server/fetch_description/meshes/forearm_roll_link.dae OR collada_web_server/fetch_description/meshes/shoulder_pan_link.dae OR collada_web_server/fetch_description/meshes/torso_lift_link.dae OR collada_web_server/fetch_description/meshes/wrist_flex_link.dae OR collada_web_server/fetch_description/meshes/head_pan_link.dae" scale="1 1 1"/>
      </geometry>
    </visual>
  </link>
  <link name="new_ragdoll__neck">
    <inertial>
      <mass value="1.03"/>
      <origin rpy="0  0  0" xyz="0.0654  0      0"/>
      <inertia ixx="0.0018" ixy="0.000000" ixz="0.000000" iyy="0.0022" iyz="0.000000" izz="0.0028"/>
    </inertial>
    <collision name="new_ragdoll__neck_collision">
      <origin rpy="0  0  0" xyz="0  0  0"/>
      <geometry>
        <mesh filename="package://ezgripper_driver/meshes/visual/SAKE_Finger.stl OR ezgripper_driver/meshes/visual/SAKE_Palm_Quad.stl OR ezgripper_driver/meshes/visual/SAKE_Palm_Dual.stl OR ezgripper_driver/meshes/collision/SAKE_Finger.stl OR ezgripper_driver/meshes/collision/SAKE_Palm_Quad.stl OR ezgripper_driver/meshes/collision/SAKE_Palm_Dual.stl OR ezgripper_driver/meshes/ezgripper_gen2/SAKE_Palm_Dual_Gen2.stl OR ezgripper_driver/meshes/ezgripper_gen2/SAKE_Finger_L1_Gen2.stl OR ezgripper_driver/meshes/ezgripper_gen2/SAKE_Finger_L2_Gen2.stl OR access_teleop/models/ragdoll/model.dae OR access_teleop/files/model_files/collada/cube_l.dae OR access_teleop/files/model_files/collada/ball.dae OR access_teleop/files/model_files/collada/cube_s.dae OR access_teleop/files/model_files/collada/cube_m.dae OR access_teleop/files/model_files/collada/stone.dae OR access_teleop/files/model_files/collada/cube_xl.dae OR access_teleop/files/model_files/collada/shelf.dae OR collada_web_server/fetch_description/meshes/gripper_link.dae OR collada_web_server/fetch_description/meshes/elbow_flex_link.dae OR collada_web_server/fetch_description/meshes/torso_fixed_link.dae OR collada_web_server/fetch_description/meshes/base_link.dae OR collada_web_server/fetch_description/meshes/shoulder_lift_link.dae OR collada_web_server/fetch_description/meshes/wrist_roll_link.dae OR collada_web_server/fetch_description/meshes/head_tilt_link.dae OR collada_web_server/fetch_description/meshes/upperarm_roll_link.dae OR collada_web_server/fetch_description/meshes/forearm_roll_link.dae OR collada_web_server/fetch_description/meshes/shoulder_pan_link.dae OR collada_web_server/fetch_description/meshes/torso_lift_link.dae OR collada_web_server/fetch_description/meshes/wrist_flex_link.dae OR collada_web_server/fetch_description/meshes/head_pan_link.dae" scale="1 1 1"/>
      </geometry>
    </collision>
    <visual name="new_ragdoll__neck_geom_visual">
      <origin rpy="0  0  0" xyz="0  0  0"/>
      <geometry>
        <mesh filename="package://ezgripper_driver/meshes/visual/SAKE_Finger.stl OR ezgripper_driver/meshes/visual/SAKE_Palm_Quad.stl OR ezgripper_driver/meshes/visual/SAKE_Palm_Dual.stl OR ezgripper_driver/meshes/collision/SAKE_Finger.stl OR ezgripper_driver/meshes/collision/SAKE_Palm_Quad.stl OR ezgripper_driver/meshes/collision/SAKE_Palm_Dual.stl OR ezgripper_driver/meshes/ezgripper_gen2/SAKE_Palm_Dual_Gen2.stl OR ezgripper_driver/meshes/ezgripper_gen2/SAKE_Finger_L1_Gen2.stl OR ezgripper_driver/meshes/ezgripper_gen2/SAKE_Finger_L2_Gen2.stl OR access_teleop/models/ragdoll/model.dae OR access_teleop/files/model_files/collada/cube_l.dae OR access_teleop/files/model_files/collada/ball.dae OR access_teleop/files/model_files/collada/cube_s.dae OR access_teleop/files/model_files/collada/cube_m.dae OR access_teleop/files/model_files/collada/stone.dae OR access_teleop/files/model_files/collada/cube_xl.dae OR access_teleop/files/model_files/collada/shelf.dae OR collada_web_server/fetch_description/meshes/gripper_link.dae OR collada_web_server/fetch_description/meshes/elbow_flex_link.dae OR collada_web_server/fetch_description/meshes/torso_fixed_link.dae OR collada_web_server/fetch_description/meshes/base_link.dae OR collada_web_server/fetch_description/meshes/shoulder_lift_link.dae OR collada_web_server/fetch_description/meshes/wrist_roll_link.dae OR collada_web_server/fetch_description/meshes/head_tilt_link.dae OR collada_web_server/fetch_description/meshes/upperarm_roll_link.dae OR collada_web_server/fetch_description/meshes/forearm_roll_link.dae OR collada_web_server/fetch_description/meshes/shoulder_pan_link.dae OR collada_web_server/fetch_description/meshes/torso_lift_link.dae OR collada_web_server/fetch_description/meshes/wrist_flex_link.dae OR collada_web_server/fetch_description/meshes/head_pan_link.dae" scale="1 1 1"/>
      </geometry>
    </visual>
  </link>
  <link name="new_ragdoll__head">
    <inertial>
      <mass value="6.02"/>
      <origin rpy="0  0  0" xyz="0.09779  0.0508   0"/>
      <inertia ixx="0.0206" ixy="0.000000" ixz="0.000000" iyy="0.0235" iyz="0.000000" izz="0.0153"/>
    </inertial>
    <collision name="new_ragdoll__head_collision">
      <origin rpy="3.14159000e+00   1.59000000e-03   3.14159000e+00" xyz="0  0  0"/>
      <geometry>
        <mesh filename="package://ezgripper_driver/meshes/visual/SAKE_Finger.stl OR ezgripper_driver/meshes/visual/SAKE_Palm_Quad.stl OR ezgripper_driver/meshes/visual/SAKE_Palm_Dual.stl OR ezgripper_driver/meshes/collision/SAKE_Finger.stl OR ezgripper_driver/meshes/collision/SAKE_Palm_Quad.stl OR ezgripper_driver/meshes/collision/SAKE_Palm_Dual.stl OR ezgripper_driver/meshes/ezgripper_gen2/SAKE_Palm_Dual_Gen2.stl OR ezgripper_driver/meshes/ezgripper_gen2/SAKE_Finger_L1_Gen2.stl OR ezgripper_driver/meshes/ezgripper_gen2/SAKE_Finger_L2_Gen2.stl OR access_teleop/models/ragdoll/model.dae OR access_teleop/files/model_files/collada/cube_l.dae OR access_teleop/files/model_files/collada/ball.dae OR access_teleop/files/model_files/collada/cube_s.dae OR access_teleop/files/model_files/collada/cube_m.dae OR access_teleop/files/model_files/collada/stone.dae OR access_teleop/files/model_files/collada/cube_xl.dae OR access_teleop/files/model_files/collada/shelf.dae OR collada_web_server/fetch_description/meshes/gripper_link.dae OR collada_web_server/fetch_description/meshes/elbow_flex_link.dae OR collada_web_server/fetch_description/meshes/torso_fixed_link.dae OR collada_web_server/fetch_description/meshes/base_link.dae OR collada_web_server/fetch_description/meshes/shoulder_lift_link.dae OR collada_web_server/fetch_description/meshes/wrist_roll_link.dae OR collada_web_server/fetch_description/meshes/head_tilt_link.dae OR collada_web_server/fetch_description/meshes/upperarm_roll_link.dae OR collada_web_server/fetch_description/meshes/forearm_roll_link.dae OR collada_web_server/fetch_description/meshes/shoulder_pan_link.dae OR collada_web_server/fetch_description/meshes/torso_lift_link.dae OR collada_web_server/fetch_description/meshes/wrist_flex_link.dae OR collada_web_server/fetch_description/meshes/head_pan_link.dae" scale="1 1 1"/>
      </geometry>
    </collision>
    <visual name="new_ragdoll__head_visual">
      <origin rpy="3.14159000e+00   1.59000000e-03   3.14159000e+00" xyz="0  0  0"/>
      <geometry>
        <mesh filename="package://ezgripper_driver/meshes/visual/SAKE_Finger.stl OR ezgripper_driver/meshes/visual/SAKE_Palm_Quad.stl OR ezgripper_driver/meshes/visual/SAKE_Palm_Dual.stl OR ezgripper_driver/meshes/collision/SAKE_Finger.stl OR ezgripper_driver/meshes/collision/SAKE_Palm_Quad.stl OR ezgripper_driver/meshes/collision/SAKE_Palm_Dual.stl OR ezgripper_driver/meshes/ezgripper_gen2/SAKE_Palm_Dual_Gen2.stl OR ezgripper_driver/meshes/ezgripper_gen2/SAKE_Finger_L1_Gen2.stl OR ezgripper_driver/meshes/ezgripper_gen2/SAKE_Finger_L2_Gen2.stl OR access_teleop/models/ragdoll/model.dae OR access_teleop/files/model_files/collada/cube_l.dae OR access_teleop/files/model_files/collada/ball.dae OR access_teleop/files/model_files/collada/cube_s.dae OR access_teleop/files/model_files/collada/cube_m.dae OR access_teleop/files/model_files/collada/stone.dae OR access_teleop/files/model_files/collada/cube_xl.dae OR access_teleop/files/model_files/collada/shelf.dae OR collada_web_server/fetch_description/meshes/gripper_link.dae OR collada_web_server/fetch_description/meshes/elbow_flex_link.dae OR collada_web_server/fetch_description/meshes/torso_fixed_link.dae OR collada_web_server/fetch_description/meshes/base_link.dae OR collada_web_server/fetch_description/meshes/shoulder_lift_link.dae OR collada_web_server/fetch_description/meshes/wrist_roll_link.dae OR collada_web_server/fetch_description/meshes/head_tilt_link.dae OR collada_web_server/fetch_description/meshes/upperarm_roll_link.dae OR collada_web_server/fetch_description/meshes/forearm_roll_link.dae OR collada_web_server/fetch_description/meshes/shoulder_pan_link.dae OR collada_web_server/fetch_description/meshes/torso_lift_link.dae OR collada_web_server/fetch_description/meshes/wrist_flex_link.dae OR collada_web_server/fetch_description/meshes/head_pan_link.dae" scale="1 1 1"/>
      </geometry>
    </visual>
  </link>
  <link name="new_ragdoll__r_arm">
    <inertial>
      <mass value="2.35"/>
      <origin rpy="0  0  0" xyz="-0.141    0      -0.04953"/>
      <inertia ixx="0.0141" ixy="0.000000" ixz="0.000000" iyy="0.0141" iyz="0.000000" izz="0.0029"/>
    </inertial>
    <collision name="new_ragdoll__r_arm_collision">
      <origin rpy="0  0  0" xyz="-0.141    0      -0.04953"/>
      <geometry>
        <mesh filename="package://ezgripper_driver/meshes/visual/SAKE_Finger.stl OR ezgripper_driver/meshes/visual/SAKE_Palm_Quad.stl OR ezgripper_driver/meshes/visual/SAKE_Palm_Dual.stl OR ezgripper_driver/meshes/collision/SAKE_Finger.stl OR ezgripper_driver/meshes/collision/SAKE_Palm_Quad.stl OR ezgripper_driver/meshes/collision/SAKE_Palm_Dual.stl OR ezgripper_driver/meshes/ezgripper_gen2/SAKE_Palm_Dual_Gen2.stl OR ezgripper_driver/meshes/ezgripper_gen2/SAKE_Finger_L1_Gen2.stl OR ezgripper_driver/meshes/ezgripper_gen2/SAKE_Finger_L2_Gen2.stl OR access_teleop/models/ragdoll/model.dae OR access_teleop/files/model_files/collada/cube_l.dae OR access_teleop/files/model_files/collada/ball.dae OR access_teleop/files/model_files/collada/cube_s.dae OR access_teleop/files/model_files/collada/cube_m.dae OR access_teleop/files/model_files/collada/stone.dae OR access_teleop/files/model_files/collada/cube_xl.dae OR access_teleop/files/model_files/collada/shelf.dae OR collada_web_server/fetch_description/meshes/gripper_link.dae OR collada_web_server/fetch_description/meshes/elbow_flex_link.dae OR collada_web_server/fetch_description/meshes/torso_fixed_link.dae OR collada_web_server/fetch_description/meshes/base_link.dae OR collada_web_server/fetch_description/meshes/shoulder_lift_link.dae OR collada_web_server/fetch_description/meshes/wrist_roll_link.dae OR collada_web_server/fetch_description/meshes/head_tilt_link.dae OR collada_web_server/fetch_description/meshes/upperarm_roll_link.dae OR collada_web_server/fetch_description/meshes/forearm_roll_link.dae OR collada_web_server/fetch_description/meshes/shoulder_pan_link.dae OR collada_web_server/fetch_description/meshes/torso_lift_link.dae OR collada_web_server/fetch_description/meshes/wrist_flex_link.dae OR collada_web_server/fetch_description/meshes/head_pan_link.dae" scale="1 1 1"/>
      </geometry>
    </collision>
    <visual name="new_ragdoll__r_arm_visual">
      <origin rpy="0  0  0" xyz="-0.141    0      -0.04953"/>
      <geometry>
        <mesh filename="package://ezgripper_driver/meshes/visual/SAKE_Finger.stl OR ezgripper_driver/meshes/visual/SAKE_Palm_Quad.stl OR ezgripper_driver/meshes/visual/SAKE_Palm_Dual.stl OR ezgripper_driver/meshes/collision/SAKE_Finger.stl OR ezgripper_driver/meshes/collision/SAKE_Palm_Quad.stl OR ezgripper_driver/meshes/collision/SAKE_Palm_Dual.stl OR ezgripper_driver/meshes/ezgripper_gen2/SAKE_Palm_Dual_Gen2.stl OR ezgripper_driver/meshes/ezgripper_gen2/SAKE_Finger_L1_Gen2.stl OR ezgripper_driver/meshes/ezgripper_gen2/SAKE_Finger_L2_Gen2.stl OR access_teleop/models/ragdoll/model.dae OR access_teleop/files/model_files/collada/cube_l.dae OR access_teleop/files/model_files/collada/ball.dae OR access_teleop/files/model_files/collada/cube_s.dae OR access_teleop/files/model_files/collada/cube_m.dae OR access_teleop/files/model_files/collada/stone.dae OR access_teleop/files/model_files/collada/cube_xl.dae OR access_teleop/files/model_files/collada/shelf.dae OR collada_web_server/fetch_description/meshes/gripper_link.dae OR collada_web_server/fetch_description/meshes/elbow_flex_link.dae OR collada_web_server/fetch_description/meshes/torso_fixed_link.dae OR collada_web_server/fetch_description/meshes/base_link.dae OR collada_web_server/fetch_description/meshes/shoulder_lift_link.dae OR collada_web_server/fetch_description/meshes/wrist_roll_link.dae OR collada_web_server/fetch_description/meshes/head_tilt_link.dae OR collada_web_server/fetch_description/meshes/upperarm_roll_link.dae OR collada_web_server/fetch_description/meshes/forearm_roll_link.dae OR collada_web_server/fetch_description/meshes/shoulder_pan_link.dae OR collada_web_server/fetch_description/meshes/torso_lift_link.dae OR collada_web_server/fetch_description/meshes/wrist_flex_link.dae OR collada_web_server/fetch_description/meshes/head_pan_link.dae" scale="1 1 1"/>
      </geometry>
    </visual>
  </link>
  <link name="new_ragdoll__r_wrist">
    <inertial>
      <mass value="1.4"/>
      <origin rpy="0  0  0" xyz="-0.1257  0      0"/>
      <inertia ixx="0.009" ixy="0.000000" ixz="0.000000" iyy="0.009" iyz="0.000000" izz="0.0014"/>
    </inertial>
    <collision name="new_ragdoll__r_wrist_collision">
      <origin rpy="0  0  0" xyz="-0.1257  0      0"/>
      <geometry>
        <mesh filename="package://ezgripper_driver/meshes/visual/SAKE_Finger.stl OR ezgripper_driver/meshes/visual/SAKE_Palm_Quad.stl OR ezgripper_driver/meshes/visual/SAKE_Palm_Dual.stl OR ezgripper_driver/meshes/collision/SAKE_Finger.stl OR ezgripper_driver/meshes/collision/SAKE_Palm_Quad.stl OR ezgripper_driver/meshes/collision/SAKE_Palm_Dual.stl OR ezgripper_driver/meshes/ezgripper_gen2/SAKE_Palm_Dual_Gen2.stl OR ezgripper_driver/meshes/ezgripper_gen2/SAKE_Finger_L1_Gen2.stl OR ezgripper_driver/meshes/ezgripper_gen2/SAKE_Finger_L2_Gen2.stl OR access_teleop/models/ragdoll/model.dae OR access_teleop/files/model_files/collada/cube_l.dae OR access_teleop/files/model_files/collada/ball.dae OR access_teleop/files/model_files/collada/cube_s.dae OR access_teleop/files/model_files/collada/cube_m.dae OR access_teleop/files/model_files/collada/stone.dae OR access_teleop/files/model_files/collada/cube_xl.dae OR access_teleop/files/model_files/collada/shelf.dae OR collada_web_server/fetch_description/meshes/gripper_link.dae OR collada_web_server/fetch_description/meshes/elbow_flex_link.dae OR collada_web_server/fetch_description/meshes/torso_fixed_link.dae OR collada_web_server/fetch_description/meshes/base_link.dae OR collada_web_server/fetch_description/meshes/shoulder_lift_link.dae OR collada_web_server/fetch_description/meshes/wrist_roll_link.dae OR collada_web_server/fetch_description/meshes/head_tilt_link.dae OR collada_web_server/fetch_description/meshes/upperarm_roll_link.dae OR collada_web_server/fetch_description/meshes/forearm_roll_link.dae OR collada_web_server/fetch_description/meshes/shoulder_pan_link.dae OR collada_web_server/fetch_description/meshes/torso_lift_link.dae OR collada_web_server/fetch_description/meshes/wrist_flex_link.dae OR collada_web_server/fetch_description/meshes/head_pan_link.dae" scale="1 1 1"/>
      </geometry>
    </collision>
    <visual name="new_ragdoll__r_wrist_visual">
      <origin rpy="0  0  0" xyz="-0.1257  0      0"/>
      <geometry>
        <mesh filename="package://ezgripper_driver/meshes/visual/SAKE_Finger.stl OR ezgripper_driver/meshes/visual/SAKE_Palm_Quad.stl OR ezgripper_driver/meshes/visual/SAKE_Palm_Dual.stl OR ezgripper_driver/meshes/collision/SAKE_Finger.stl OR ezgripper_driver/meshes/collision/SAKE_Palm_Quad.stl OR ezgripper_driver/meshes/collision/SAKE_Palm_Dual.stl OR ezgripper_driver/meshes/ezgripper_gen2/SAKE_Palm_Dual_Gen2.stl OR ezgripper_driver/meshes/ezgripper_gen2/SAKE_Finger_L1_Gen2.stl OR ezgripper_driver/meshes/ezgripper_gen2/SAKE_Finger_L2_Gen2.stl OR access_teleop/models/ragdoll/model.dae OR access_teleop/files/model_files/collada/cube_l.dae OR access_teleop/files/model_files/collada/ball.dae OR access_teleop/files/model_files/collada/cube_s.dae OR access_teleop/files/model_files/collada/cube_m.dae OR access_teleop/files/model_files/collada/stone.dae OR access_teleop/files/model_files/collada/cube_xl.dae OR access_teleop/files/model_files/collada/shelf.dae OR collada_web_server/fetch_description/meshes/gripper_link.dae OR collada_web_server/fetch_description/meshes/elbow_flex_link.dae OR collada_web_server/fetch_description/meshes/torso_fixed_link.dae OR collada_web_server/fetch_description/meshes/base_link.dae OR collada_web_server/fetch_description/meshes/shoulder_lift_link.dae OR collada_web_server/fetch_description/meshes/wrist_roll_link.dae OR collada_web_server/fetch_description/meshes/head_tilt_link.dae OR collada_web_server/fetch_description/meshes/upperarm_roll_link.dae OR collada_web_server/fetch_description/meshes/forearm_roll_link.dae OR collada_web_server/fetch_description/meshes/shoulder_pan_link.dae OR collada_web_server/fetch_description/meshes/torso_lift_link.dae OR collada_web_server/fetch_description/meshes/wrist_flex_link.dae OR collada_web_server/fetch_description/meshes/head_pan_link.dae" scale="1 1 1"/>
      </geometry>
    </visual>
  </link>
  <link name="new_ragdoll__r_hand">
    <inertial>
      <mass value="0.5"/>
      <origin rpy="0  0  0" xyz="-0.105  0     0"/>
      <inertia ixx="0.0013" ixy="0.000000" ixz="0.000000" iyy="0.0011" iyz="0.000000" izz="0.0004"/>
    </inertial>
    <collision name="new_ragdoll__r_hand_collision">
      <origin rpy="0  0  0" xyz="0  0  0"/>
      <geometry>
        <mesh filename="package://ezgripper_driver/meshes/visual/SAKE_Finger.stl OR ezgripper_driver/meshes/visual/SAKE_Palm_Quad.stl OR ezgripper_driver/meshes/visual/SAKE_Palm_Dual.stl OR ezgripper_driver/meshes/collision/SAKE_Finger.stl OR ezgripper_driver/meshes/collision/SAKE_Palm_Quad.stl OR ezgripper_driver/meshes/collision/SAKE_Palm_Dual.stl OR ezgripper_driver/meshes/ezgripper_gen2/SAKE_Palm_Dual_Gen2.stl OR ezgripper_driver/meshes/ezgripper_gen2/SAKE_Finger_L1_Gen2.stl OR ezgripper_driver/meshes/ezgripper_gen2/SAKE_Finger_L2_Gen2.stl OR access_teleop/models/ragdoll/model.dae OR access_teleop/files/model_files/collada/cube_l.dae OR access_teleop/files/model_files/collada/ball.dae OR access_teleop/files/model_files/collada/cube_s.dae OR access_teleop/files/model_files/collada/cube_m.dae OR access_teleop/files/model_files/collada/stone.dae OR access_teleop/files/model_files/collada/cube_xl.dae OR access_teleop/files/model_files/collada/shelf.dae OR collada_web_server/fetch_description/meshes/gripper_link.dae OR collada_web_server/fetch_description/meshes/elbow_flex_link.dae OR collada_web_server/fetch_description/meshes/torso_fixed_link.dae OR collada_web_server/fetch_description/meshes/base_link.dae OR collada_web_server/fetch_description/meshes/shoulder_lift_link.dae OR collada_web_server/fetch_description/meshes/wrist_roll_link.dae OR collada_web_server/fetch_description/meshes/head_tilt_link.dae OR collada_web_server/fetch_description/meshes/upperarm_roll_link.dae OR collada_web_server/fetch_description/meshes/forearm_roll_link.dae OR collada_web_server/fetch_description/meshes/shoulder_pan_link.dae OR collada_web_server/fetch_description/meshes/torso_lift_link.dae OR collada_web_server/fetch_description/meshes/wrist_flex_link.dae OR collada_web_server/fetch_description/meshes/head_pan_link.dae" scale="1 1 1"/>
      </geometry>
    </collision>
    <visual name="new_ragdoll__r_hand_visual">
      <origin rpy="0  0  0" xyz="0  0  0"/>
      <geometry>
        <mesh filename="package://ezgripper_driver/meshes/visual/SAKE_Finger.stl OR ezgripper_driver/meshes/visual/SAKE_Palm_Quad.stl OR ezgripper_driver/meshes/visual/SAKE_Palm_Dual.stl OR ezgripper_driver/meshes/collision/SAKE_Finger.stl OR ezgripper_driver/meshes/collision/SAKE_Palm_Quad.stl OR ezgripper_driver/meshes/collision/SAKE_Palm_Dual.stl OR ezgripper_driver/meshes/ezgripper_gen2/SAKE_Palm_Dual_Gen2.stl OR ezgripper_driver/meshes/ezgripper_gen2/SAKE_Finger_L1_Gen2.stl OR ezgripper_driver/meshes/ezgripper_gen2/SAKE_Finger_L2_Gen2.stl OR access_teleop/models/ragdoll/model.dae OR access_teleop/files/model_files/collada/cube_l.dae OR access_teleop/files/model_files/collada/ball.dae OR access_teleop/files/model_files/collada/cube_s.dae OR access_teleop/files/model_files/collada/cube_m.dae OR access_teleop/files/model_files/collada/stone.dae OR access_teleop/files/model_files/collada/cube_xl.dae OR access_teleop/files/model_files/collada/shelf.dae OR collada_web_server/fetch_description/meshes/gripper_link.dae OR collada_web_server/fetch_description/meshes/elbow_flex_link.dae OR collada_web_server/fetch_description/meshes/torso_fixed_link.dae OR collada_web_server/fetch_description/meshes/base_link.dae OR collada_web_server/fetch_description/meshes/shoulder_lift_link.dae OR collada_web_server/fetch_description/meshes/wrist_roll_link.dae OR collada_web_server/fetch_description/meshes/head_tilt_link.dae OR collada_web_server/fetch_description/meshes/upperarm_roll_link.dae OR collada_web_server/fetch_description/meshes/forearm_roll_link.dae OR collada_web_server/fetch_description/meshes/shoulder_pan_link.dae OR collada_web_server/fetch_description/meshes/torso_lift_link.dae OR collada_web_server/fetch_description/meshes/wrist_flex_link.dae OR collada_web_server/fetch_description/meshes/head_pan_link.dae" scale="1 1 1"/>
      </geometry>
    </visual>
  </link>
  <link name="new_ragdoll__v_r_arm">
    <inertial>
      <mass value="0"/>
      <origin rpy="0  0  0" xyz="0  0  0"/>
      <inertia ixx="0" ixy="0" ixz="0" iyy="0" iyz="0" izz="0"/>
    </inertial>
    <collision name="new_ragdoll__v_r_arm_collision">
      <origin rpy="0  0  0" xyz="0  0  0"/>
      <geometry>
        <box size="0.0 0.0 0.0"/>
      </geometry>
    </collision>
  </link>
  <link name="new_ragdoll__v_l_arm">
    <inertial>
      <mass value="0"/>
      <origin rpy="0  0  0" xyz="0  0  0"/>
      <inertia ixx="0" ixy="0" ixz="0" iyy="0" iyz="0" izz="0"/>
    </inertial>
    <collision name="new_ragdoll__v_l_arm_collision">
      <origin rpy="0  0  0" xyz="0  0  0"/>
      <geometry>
        <box size="0.0 0.0 0.0"/>
      </geometry>
    </collision>
  </link>
  <link name="new_ragdoll__v_l_thigh">
    <inertial>
      <mass value="0"/>
      <origin rpy="0  0  0" xyz="0  0  0"/>
      <inertia ixx="0" ixy="0" ixz="0" iyy="0" iyz="0" izz="0"/>
    </inertial>
    <collision name="new_ragdoll__v_l_thigh_collision">
      <origin rpy="0  0  0" xyz="0  0  0"/>
      <geometry>
        <box size="0.0 0.0 0.0"/>
      </geometry>
    </collision>
  </link>
  <link name="new_ragdoll__v_r_thigh">
    <inertial>
      <mass value="0"/>
      <origin rpy="0  0  0" xyz="0  0  0"/>
      <inertia ixx="0" ixy="0" ixz="0" iyy="0" iyz="0" izz="0"/>
    </inertial>
    <collision name="new_ragdoll__v_r_thigh_collision">
      <origin rpy="0  0  0" xyz="0  0  0"/>
      <geometry>
        <box size="0.0 0.0 0.0"/>
      </geometry>
    </collision>
  </link>
</robot>
