<?xml version="1.0" ?>
<!-- this was initially generated from ragdoll.urdf,
     but have sence been updated to turn off gravity for certain links
     and various tweaks -->

<sdf version="1.4">
    <model name="new_ragdoll">
        <!--<pose>0.000000 0.000000 10 1.57 -0.000000 0.000000</pose>-->
        <pose>0.000000 0.000000 10.0 0.0 -1.570000 0.000000</pose>-->
        <link name="lower_body">
            <pose>0.000000 0.000000 0.000000 0.000000 -0.000000 0.000000</pose>
            <inertial>
                <pose>0.0762 0.000000 0.000000 0.000000 -0.000000 0.000000</pose>
                <inertia>
                    <ixx>0.1116</ixx>
                    <ixy>0.000000</ixy>
                    <ixz>0.000000</ixz>
                    <iyy>0.1028</iyy>
                    <iyz>0.000000</iyz>
                    <izz>0.1298</izz>
                </inertia>
                <mass>9.7</mass>
            </inertial>
            <collision name="lower_body_collision">
                <pose>0.000000 0.000000 0.000000 0.000000 -0.000000 0.000000</pose>
                <geometry>
                    <mesh>
                        <scale>1 1 1</scale>
                        <uri>model://Test_Lower_Body_m.STL</uri>
                    </mesh>
                </geometry>
                <surface>
                    <friction>
                        <ode>
                            <mu>1.000000</mu>
                            <mu2>1.000000</mu2>
                            <fdir1>0.000000 0.000000 0.000000</fdir1>
                            <slip1>0.000000</slip1>
                            <slip2>0.000000</slip2>
                        </ode>
                    </friction>
                    <bounce>
                        <restitution_coefficient>0.000000</restitution_coefficient>
                        <threshold>100000.000000</threshold>
                    </bounce>
                    <contact>
                        <ode>
                            <!--<soft_cfm>0.000000</soft_cfm>
                            <soft_erp>0.200000</soft_erp>
                            <kp>1000000000000.000000</kp>
                            <kd>1.000000</kd>-->
                            <soft_cfm>0.0</soft_cfm>
                            <soft_erp>0.200000</soft_erp>
                            <kp>50000.000000</kp>
                            <kd>5000.000000</kd>-->
                            <max_vel>0.000000</max_vel>
                            <min_depth>0.001000</min_depth>
                        </ode>
                    </contact>
                </surface>
                <laser_retro>0.000000</laser_retro>
            </collision>
            <visual name="lower_body_visual">
                <pose>0.000000 0.000000 0.000000 0.000000 -0.000000 0.000000</pose>
                <geometry>
                    <mesh>
                        <scale>1 1 1</scale>
                        <uri>model://Test_Lower_Body_m.STL</uri>
                    </mesh>
                </geometry>
                <material>
                    <diffuse>0.0 1.0 0.0 1</diffuse>
                </material>
                <cast_shadows>0</cast_shadows>
                <laser_retro>0.000000</laser_retro>
                <transparency>0.000000</transparency>
            </visual>
            <sensor name='lower_body_tactile_sensor' type='contact'>
                <contact>
                    <collision>lower_body_collision</collision>
                    <topic>__default_topic__</topic>
                </contact>
                <plugin name="ros_tactile_plugin" filename="libros_tactile_plugin.so" />
                <always_on>1</always_on>
                <update_rate>100.0</update_rate>
                <visualize>false</visualize>
            </sensor>
            <gravity>1</gravity>
            <self_collide>0</self_collide>
            <kinematic>0</kinematic>
        </link>
        <link name="l_thigh">
            <pose>0.000000 0.000000 0.0864 0.000000 -0.000000 0.000000</pose>
            <inertial>
                <pose>-0.21336 0.000000 0.000000 0.000000 -0.000000 0.000000</pose>
                <inertia>
                    <ixx>0.1652</ixx>
                    <ixy>0.000000</ixy>
                    <ixz>0.000000</ixz>
                    <iyy>0.1652</iyy>
                    <iyz>0.000000</iyz>
                    <izz>0.0452</izz>
                </inertia>
                <mass>12.3</mass>
            </inertial>
            <collision name="l_thigh_collision">
                <pose>-0.21336 0.000000 -0.000000 0.000000 -0.000000 0.000000</pose>
                <geometry>
                    <mesh>
                        <scale>1 1 1</scale>
                        <uri>model://Test_Thigh_m.STL</uri>
                    </mesh>
                </geometry>
                <surface>
                    <friction>
                        <ode>
                            <mu>1.000000</mu>
                            <mu2>1.000000</mu2>
                            <fdir1>0.000000 0.000000 0.000000</fdir1>
                            <slip1>0.000000</slip1>
                            <slip2>0.000000</slip2>
                        </ode>
                    </friction>
                    <bounce>
                        <restitution_coefficient>0.000000</restitution_coefficient>
                        <threshold>100000.000000</threshold>
                    </bounce>
                    <contact>
                        <ode>
                            <soft_cfm>0.0</soft_cfm>
                            <soft_erp>0.200000</soft_erp>
                            <kp>50000.000000</kp>
                            <kd>5000.000000</kd>
                            <max_vel>0.000000</max_vel>
                            <min_depth>0.001000</min_depth>
                        </ode>
                    </contact>
                </surface>
                <laser_retro>0.000000</laser_retro>
            </collision>
            <visual name="l_thigh_visual">
                <pose>-0.21336 0.000000 -0.000000 0.000000 -0.000000 0.000000</pose>
                <geometry>
                    <mesh>
                        <scale>1 1 1</scale>
                        <uri>model://Test_Thigh_m.STL</uri>
                    </mesh>
                </geometry>
                <cast_shadows>0</cast_shadows>
                <laser_retro>0.000000</laser_retro>
                <transparency>0.000000</transparency>
                <material>
                    <diffuse>0.0 1.0 0.0 1</diffuse>
                </material>
            </visual>
            <sensor name='l_thigh_tactile_sensor' type='contact'>
                <contact>
                    <collision>l_thigh_collision</collision>
                    <topic>__default_topic__</topic>
                </contact>
                <plugin name="ros_tactile_plugin" filename="libros_tactile_plugin.so" />
                <always_on>1</always_on>
                <update_rate>100.0</update_rate>
                <visualize>false</visualize>
            </sensor>
            <gravity>1</gravity>
            <self_collide>0</self_collide>
            <kinematic>0</kinematic>
        </link>
        <link name="l_shin">
            <pose>-0.42672 -0.000000 0.0864 0.000000 -0.000000 0.000000</pose>
            <inertial>
                <pose>-0.20701 0.000000 -0.000000 0.000000 -0.000000 0.000000</pose>
                <inertia>
                    <ixx>0.0606</ixx>
                    <ixy>0.000000</ixy>
                    <ixz>0.000000</ixz>
                    <iyy>0.0606</iyy>
                    <iyz>0.000000</iyz>
                    <izz>0.0071</izz>
                </inertia>
                <mass>3.76</mass>
            </inertial>
            <collision name="l_shin_collision">
                <pose>-0.20701 0.000000 -0.000000 0.000000 -0.000000 0.000000</pose>
                <geometry>
                    <mesh>
                        <scale>1 1 1</scale>
                        <uri>model://Test_Shin_m.STL</uri>
                    </mesh>
                </geometry>
                <surface>
                    <friction>
                        <ode>
                            <mu>1.000000</mu>
                            <mu2>1.000000</mu2>
                            <fdir1>0.000000 0.000000 0.000000</fdir1>
                            <slip1>0.000000</slip1>
                            <slip2>0.000000</slip2>
                        </ode>
                    </friction>
                    <bounce>
                        <restitution_coefficient>0.000000</restitution_coefficient>
                        <threshold>100000.000000</threshold>
                    </bounce>
                    <contact>
                        <ode>
                            <soft_cfm>0.0</soft_cfm>
                            <soft_erp>0.200000</soft_erp>
                            <kp>50000.000000</kp>
                            <kd>5000.000000</kd>
                            <max_vel>0.000000</max_vel>
                            <min_depth>0.001000</min_depth>
                        </ode>
                    </contact>
                </surface>
                <laser_retro>0.000000</laser_retro>
            </collision>
            <visual name="l_shin_visual">
                <pose>-0.20701 0.000000 -0.000000 0.000000 -0.000000 0.000000</pose>
                <geometry>
                    <mesh>
                        <scale>1 1 1</scale>
                        <uri>model://Test_Shin_m.STL</uri>
                    </mesh>
                </geometry>
                <cast_shadows>0</cast_shadows>
                <laser_retro>0.000000</laser_retro>
                <transparency>0.000000</transparency>
                <material>
                    <diffuse>0.0 1.0 0.0 1</diffuse>
                </material>
            </visual>
            <sensor name='l_shin_tactile_sensor' type='contact'>
                <contact>
                    <collision>l_shin_collision</collision>
                    <topic>__default_topic__</topic>
                </contact>
                <plugin name="ros_tactile_plugin" filename="libros_tactile_plugin.so" />
                <always_on>1</always_on>
                <update_rate>100.0</update_rate>
                <visualize>false</visualize>
            </sensor>
            <gravity>1</gravity>
            <self_collide>0</self_collide>
            <kinematic>0</kinematic>
        </link>
        <link name="l_foot">
            <pose>-0.84074 -0.000000 0.0864 0.000000 -0.000000 0.000000</pose>
            <inertial>
                <pose>-0.059182 0.0508 -0.000000 0.000000 -0.000000 0.000000</pose>
                <inertia>
                    <ixx>0.0008</ixx>
                    <ixy>0.000000</ixy>
                    <ixz>0.000000</ixz>
                    <iyy>0.0044</iyy>
                    <iyz>0.000000</iyz>
                    <izz>0.0046</izz>
                </inertia>
                <mass>1.19</mass>
        </inertial>
            <collision name="l_foot_geom">
                <pose>0.000000 0.000000 -0.000000 0.000000 -0.000000 0.000000</pose>
                <geometry>
                    <mesh>
                        <scale>1 1 1</scale>
                        <uri>model://Test_Foot_m.STL</uri>
                    </mesh>
                </geometry>
                <surface>
                    <friction>
                        <ode>
                            <mu>1.000000</mu>
                            <mu2>1.000000</mu2>
                            <fdir1>0.000000 0.000000 0.000000</fdir1>
                            <slip1>0.000000</slip1>
                            <slip2>0.000000</slip2>
                        </ode>
                    </friction>
                    <bounce>
                        <restitution_coefficient>0.000000</restitution_coefficient>
                        <threshold>100000.000000</threshold>
                    </bounce>
                    <contact>
                        <ode>
                            <soft_cfm>0.0</soft_cfm>
                            <soft_erp>0.200000</soft_erp>
                            <kp>50000.000000</kp>
                            <kd>5000.000000</kd>
                            <max_vel>0.000000</max_vel>
                            <min_depth>0.001000</min_depth>
                        </ode>
                    </contact>
                </surface>
                <laser_retro>0.000000</laser_retro>
            </collision>
            <visual name="l_foot_geom_visual">
                <pose>0.000000 0.000000 -0.000000 0.000000 -0.000000 0.000000</pose>
                <geometry>
                    <mesh>
                        <scale>1 1 1</scale>
                        <uri>model://Test_Foot_m.STL</uri>
                    </mesh>
                </geometry>
                <cast_shadows>0</cast_shadows>
                <laser_retro>0.000000</laser_retro>
                <transparency>0.000000</transparency>
                <material>
                    <diffuse>0.0 1.0 0.0 1</diffuse>
                </material> 
            </visual>
            <sensor name='l_foot_tactile_sensor' type='contact'>
                <contact>
                    <collision>l_foot_geom</collision>
                    <topic>__default_topic__</topic>
                </contact>
                <plugin name="ros_tactile_plugin" filename="libros_tactile_plugin.so" />
                <always_on>1</always_on>
                <update_rate>100.0</update_rate>
                <visualize>false</visualize>
            </sensor>
            <gravity>1</gravity>
            <self_collide>0</self_collide>
            <kinematic>0</kinematic>
        </link>
        <link name="r_thigh">
            <pose>0.000000 -0.000000 -0.0864 0.000000 -0.000000 0.000000</pose>
            <inertial>
                <pose>-0.21336 0.000000 0.000000 0.000000 -0.000000 0.000000</pose>
                <inertia>
                    <ixx>0.1652</ixx>
                    <ixy>0.000000</ixy>
                    <ixz>0.000000</ixz>
                    <iyy>0.1652</iyy>
                    <iyz>0.000000</iyz>
                    <izz>0.0452</izz>
                </inertia>
                <mass>12.3</mass>
            </inertial>
            <collision name="r_thigh_collision">
                <pose>-0.21336 0.000000 -0.000000 0.000000 -0.000000 0.000000</pose>
                <geometry>
                    <mesh>
                        <scale>1 1 1</scale>
                        <uri>model://Test_Thigh_m.STL</uri>
                    </mesh>
                </geometry>
                <surface>
                    <friction>
                        <ode>
                            <mu>1.000000</mu>
                            <mu2>1.000000</mu2>
                            <fdir1>0.000000 0.000000 0.000000</fdir1>
                            <slip1>0.000000</slip1>
                            <slip2>0.000000</slip2>
                        </ode>
                    </friction>
                    <bounce>
                        <restitution_coefficient>0.000000</restitution_coefficient>
                        <threshold>100000.000000</threshold>
                    </bounce>
                    <contact>
                        <ode>
                            <soft_cfm>0.0</soft_cfm>
                            <soft_erp>0.200000</soft_erp>
                            <kp>50000.000000</kp>
                            <kd>5000.000000</kd>
                            <max_vel>0.000000</max_vel>
                            <min_depth>0.001000</min_depth>
                        </ode>
                    </contact>
                </surface>
                <laser_retro>0.000000</laser_retro>
            </collision>
            <visual name="r_thigh_visual">
                <pose>-0.21336000 0.000000 -0.000000 0.000000 -0.000000 0.000000</pose>
                <geometry>
                    <mesh>
                        <scale>1 1 1</scale>
                        <uri>model://Test_Thigh_m.STL</uri>
                    </mesh>
                </geometry>
                <material>
                    <diffuse>0.0 1.0 0.0 1</diffuse>
                </material>
                <cast_shadows>0</cast_shadows>
                <laser_retro>0.000000</laser_retro>
                <transparency>0.000000</transparency>
            </visual>
            <sensor name='r_thigh_tactile_sensor' type='contact'>
                <contact>
                    <collision>r_thigh_collision</collision>
                    <topic>__default_topic__</topic>
                </contact>
                <plugin name="ros_tactile_plugin" filename="libros_tactile_plugin.so" />
                <always_on>1</always_on>
                <update_rate>100.0</update_rate>
                <visualize>false</visualize>
            </sensor>
            <gravity>1</gravity>
            <self_collide>0</self_collide>
            <kinematic>0</kinematic>
        </link>
        <link name="r_shin">
            <pose>-0.42672 -0.000000 -0.0864 0.000000 -0.000000 0.000000</pose>
            <inertial>
                <pose>-0.20701 0.000000 -0.000000 0.000000 -0.000000 0.000000</pose>
                <inertia>
                    <ixx>0.0606</ixx>
                    <ixy>0.000000</ixy>
                    <ixz>0.000000</ixz>
                    <iyy>0.0606</iyy>
                    <iyz>0.000000</iyz>
                    <izz>0.0071</izz>
                </inertia>
                <mass>3.76</mass>
            </inertial>
            <collision name="r_shin_collision">
                <pose>-0.20701 0.000000 -0.000000 0.000000 -0.000000 0.000000</pose>
                <geometry>
                    <mesh>
                        <scale>1 1 1</scale>
                        <uri>model://Test_Shin_m.STL</uri>
                    </mesh>
                </geometry>
                <surface>
                    <friction>
                        <ode>
                            <mu>1.000000</mu>
                            <mu2>1.000000</mu2>
                            <fdir1>0.000000 0.000000 0.000000</fdir1>
                            <slip1>0.000000</slip1>
                            <slip2>0.000000</slip2>
                        </ode>
                    </friction>
                    <bounce>
                        <restitution_coefficient>0.000000</restitution_coefficient>
                        <threshold>100000.000000</threshold>
                    </bounce>
                    <contact>
                        <ode>
                            <soft_cfm>0.0</soft_cfm>
                            <soft_erp>0.200000</soft_erp>
                            <kp>50000.000000</kp>
                            <kd>5000.000000</kd>
                            <max_vel>0.000000</max_vel>
                            <min_depth>0.001000</min_depth>
                        </ode>
                    </contact>
                </surface>
                <laser_retro>0.000000</laser_retro>
            </collision>
            <visual name="r_shin_visual">
                <pose>-0.20701 0.000000 -0.000000 0.000000 -0.000000 0.000000</pose>
                <geometry>
                    <mesh>
                        <scale>1 1 1</scale>
                        <uri>model://Test_Shin_m.STL</uri>
                    </mesh>
                </geometry>
                <material>
                    <diffuse>0.0 1.0 0.0 1</diffuse>
                </material>
                <cast_shadows>0</cast_shadows>
                <laser_retro>0.000000</laser_retro>
                <transparency>0.000000</transparency>
            </visual>
            <sensor name='r_shin_tactile_sensor' type='contact'>
                <contact>
                    <collision>r_shin_collision</collision>
                    <topic>__default_topic__</topic>
                </contact>
                <plugin name="ros_tactile_plugin" filename="libros_tactile_plugin.so" />
                <always_on>1</always_on>
                <update_rate>100.0</update_rate>
                <visualize>false</visualize>
            </sensor>
            <gravity>1</gravity>
            <self_collide>0</self_collide>
            <kinematic>0</kinematic>
        </link>
        <link name="r_foot">
            <pose>-0.84074 -0.000000 -0.0864 0.000000 -0.000000 0.000000</pose>
            <inertial>
                <pose>-0.059182 0.0508 -0.000000 0.000000 -0.000000 0.000000</pose>
                <inertia>
                    <ixx>0.0008</ixx>
                    <ixy>0.000000</ixy>
                    <ixz>0.000000</ixz>
                    <iyy>0.0044</iyy>
                    <iyz>0.000000</iyz>
                    <izz>0.0046</izz>
                </inertia>
                <mass>1.19</mass>
            </inertial>
            <collision name="r_foot_collision">
                <pose>0.000000 0.000000 -0.000000 0.000000 -0.000000 0.000000</pose>
                <geometry>
                    <mesh>
                        <scale>1 1 1</scale>
                        <uri>model://Test_Foot_m.STL</uri>
                    </mesh>
                </geometry>
                <surface>
                    <friction>
                        <ode>
                            <mu>1.000000</mu>
                            <mu2>1.000000</mu2>
                            <fdir1>0.000000 0.000000 0.000000</fdir1>
                            <slip1>0.000000</slip1>
                            <slip2>0.000000</slip2>
                        </ode>
                    </friction>
                    <bounce>
                        <restitution_coefficient>0.000000</restitution_coefficient>
                        <threshold>100000.000000</threshold>
                    </bounce>
                    <contact>
                        <ode>
                            <soft_cfm>0.0</soft_cfm>
                            <soft_erp>0.200000</soft_erp>
                            <kp>50000.000000</kp>
                            <kd>5000.000000</kd>
                            <max_vel>0.000000</max_vel>
                            <min_depth>0.001000</min_depth>
                        </ode>
                    </contact>
                </surface>
                <laser_retro>0.000000</laser_retro>
            </collision>
            <visual name="r_foot_visual">
                <pose>0.000000 0.000000 -0.000000 0.000000 -0.000000 0.000000</pose>
                <geometry>
                    <mesh>
                        <scale>1 1 1</scale>
                        <uri>model://Test_Foot_m.STL</uri>
                    </mesh>
                </geometry>
                <material>
                    <diffuse>0.0 1.0 0.0 1</diffuse>
                </material>
                <cast_shadows>0</cast_shadows>
                <laser_retro>0.000000</laser_retro>
                <transparency>0.000000</transparency>
            </visual>
            <sensor name='r_foot_tactile_sensor' type='contact'>
                <contact>
                    <collision>r_foot_collision</collision>
                    <topic>__default_topic__</topic>
                </contact>
                <plugin name="ros_tactile_plugin" filename="libros_tactile_plugin.so" />
                <always_on>1</always_on>
                <update_rate>100.0</update_rate>
                <visualize>false</visualize>
            </sensor>
            <gravity>1</gravity>
            <self_collide>0</self_collide>
            <kinematic>0</kinematic>
        </link>
        <link name="middle_body">
            <pose>0.05207 0.000000 0.000000 0.000000 -0.000000 0.000000</pose>
            <inertial>
                <pose>0.1765300 0.000000 0.000000 0.000000 -0.000000 0.000000</pose>
                <inertia>
                    <ixx>0.1116</ixx>
                    <ixy>0.000000</ixy>
                    <ixz>0.000000</ixz>
                    <iyy>0.1028</iyy>
                    <iyz>0.000000</iyz>
                    <izz>0.1298</izz>
                </inertia>
                <mass>14.2</mass>
            </inertial>
            <collision name="middle_body_collision">
                <pose>0.000000 0.000000 0.000000 0.000000 -0.000000 0.000000</pose>
                <geometry>
                    <mesh>
                        <scale>1 1 1</scale>
                        <uri>model://Test_Middle_Body_m.STL</uri>
                    </mesh>
                </geometry>
                <surface>
                    <friction>
                        <ode>
                            <mu>1.000000</mu>
                            <mu2>1.000000</mu2>
                            <fdir1>0.000000 0.000000 0.000000</fdir1>
                            <slip1>0.000000</slip1>
                            <slip2>0.000000</slip2>
                        </ode>
                    </friction>
                    <bounce>
                        <restitution_coefficient>0.000000</restitution_coefficient>
                        <threshold>100000.000000</threshold>
                    </bounce>
                    <contact>
                        <ode>
                            <soft_cfm>0.0</soft_cfm>
                            <soft_erp>0.200000</soft_erp>
                            <kp>50000.000000</kp>
                            <kd>5000.000000</kd>
                            <max_vel>0.000000</max_vel>
                            <min_depth>0.001000</min_depth>
                        </ode>
                    </contact>
                </surface>
                <laser_retro>0.000000</laser_retro>
            </collision>
            <visual name="middle_body_visual">
                <pose>0.000000 0.000000 0.000000 0.000000 -0.000000 0.000000</pose>
                <geometry>
                    <mesh>
                        <scale>1 1 1</scale>
                        <uri>model://Test_Middle_Body_m.STL</uri>
                    </mesh>
                </geometry>
                <material>
                    <diffuse>0.0 1.0 0.0 1</diffuse>
                </material>
                <cast_shadows>0</cast_shadows>
                <laser_retro>0.000000</laser_retro>
                <transparency>0.000000</transparency>
            </visual>
            <sensor name='middle_body_tactile_sensor' type='contact'>
                <contact>
                    <collision>middle_body_collision</collision>
                    <topic>__default_topic__</topic>
                </contact>
                <plugin name="ros_tactile_plugin" filename="libros_tactile_plugin.so" />
                <always_on>1</always_on>
                <update_rate>100.0</update_rate>
                <visualize>false</visualize>
            </sensor>
            <gravity>1</gravity>
            <self_collide>0</self_collide>
            <kinematic>0</kinematic>
        </link>
        <link name="upper_body">
            <pose>0.2032 0.000000 0.000000 0.000000 -0.000000 0.000000</pose>
            <inertial>
                <pose>0.1778 0.000000 0.000000 0.000000 -0.000000 0.000000</pose>
                <inertia>
                    <ixx>0.1116</ixx>
                    <ixy>0.000000</ixy>
                    <ixz>0.000000</ixz>
                    <iyy>0.1028</iyy>
                    <iyz>0.000000</iyz>
                    <izz>0.1298</izz>
                </inertia>
                <mass>12.82</mass>
            </inertial>
            <collision name="upper_body_collision">
                <pose>0.000000 0.000000 0.000000 0.000000 -0.000000 0.000000</pose>
                <geometry>
                    <mesh>
                        <scale>1 1 1</scale>
                        <uri>model://Test_Upper_Body_m.STL</uri>
                    </mesh>
                </geometry>
                <surface>
                    <friction>
                        <ode>
                            <mu>1.000000</mu>
                            <mu2>1.000000</mu2>
                            <fdir1>0.000000 0.000000 0.000000</fdir1>
                            <slip1>0.000000</slip1>
                            <slip2>0.000000</slip2>
                        </ode>
                    </friction>
                    <bounce>
                        <restitution_coefficient>0.000000</restitution_coefficient>
                        <threshold>100000.000000</threshold>
                    </bounce>
                    <contact>
                        <ode>
                            <soft_cfm>0.0</soft_cfm>
                            <soft_erp>0.200000</soft_erp>
                            <kp>50000.000000</kp>
                            <kd>5000.000000</kd>
                            <max_vel>0.000000</max_vel>
                            <min_depth>0.001000</min_depth>
                        </ode>
                    </contact>
                </surface>
                <laser_retro>0.000000</laser_retro>
            </collision>
            <visual name="upper_body_visual">
                <pose>0.000000 0.000000 0.000000 0.000000 -0.000000 0.000000</pose>
                <geometry>
                    <mesh>
                        <scale>1 1 1</scale>
                        <uri>model://Test_Upper_Body_m.STL</uri>
                    </mesh>
                </geometry>
                <material>
                    <diffuse>0.0 1.0 0.0 1</diffuse>
                </material>
                <cast_shadows>0</cast_shadows>
                <laser_retro>0.000000</laser_retro>
                <transparency>0.000000</transparency>
            </visual>
            <sensor name='upper_body_tactile_sensor' type='contact'>
                <contact>
                    <collision>upper_body_collision</collision>
                    <topic>__default_topic__</topic>
                </contact>
                <plugin name="ros_tactile_plugin" filename="libros_tactile_plugin.so" />
                <always_on>1</always_on>
                <update_rate>100.0</update_rate>
                <visualize>false</visualize>
            </sensor>
            <gravity>1</gravity>
            <self_collide>0</self_collide>
            <kinematic>0</kinematic>
        </link>
        <link name="l_arm">
            <pose>0.4572 0.000000 0.17526 0 -0.000000 0.000000</pose>
            <inertial>
                <pose>-0.14097 0.000000 0.04953 0.000000 -0.000000 0.000000</pose>
                <inertia>
                    <ixx>0.0141</ixx>
                    <ixy>0.000000</ixy>
                    <ixz>0.000000</ixz>
                    <iyy>0.0141</iyy>
                    <iyz>0.000000</iyz>
                    <izz>0.0029</izz>
                </inertia>
                <mass>2.35</mass>
            </inertial>
            <collision name="l_arm_collision">
                <pose>-0.14097 0.000000 0.04953 3.14 -0.000000 0.000000</pose>
                <geometry>
                    <mesh>
                        <scale>1 1 1</scale>
                        <uri>model://Test_Arm_m.STL</uri>
                    </mesh>
                </geometry>
                <surface>
                    <friction>
                        <ode>
                            <mu>1.000000</mu>
                            <mu2>1.000000</mu2>
                            <fdir1>0.000000 0.000000 0.000000</fdir1>
                            <slip1>0.000000</slip1>
                            <slip2>0.000000</slip2>
                        </ode>
                    </friction>
                    <bounce>
                        <restitution_coefficient>0.000000</restitution_coefficient>
                        <threshold>100000.000000</threshold>
                    </bounce>
                    <contact>
                        <ode>
                            <soft_cfm>0.0</soft_cfm>
                            <soft_erp>0.200000</soft_erp>
                            <kp>50000.000000</kp>
                            <kd>5000.000000</kd>
                            <max_vel>0.000000</max_vel>
                            <min_depth>0.001000</min_depth>
                        </ode>
                    </contact>
                </surface>
                <laser_retro>0.000000</laser_retro>
            </collision>
            <visual name="l_arm_visual">
                <pose>-0.14097 0.000000 0.04953 3.14 -0.000000 0.000000</pose>
                <geometry>
                    <mesh>
                        <scale>1 1 1</scale>
                        <uri>model://Test_Arm_m.STL</uri>
                    </mesh>
                </geometry>
                <material>
                    <diffuse>0.0 1.0 0.0 1</diffuse>
                </material>
                <cast_shadows>0</cast_shadows>
                <laser_retro>0.000000</laser_retro>
                <transparency>0.000000</transparency>
            </visual>
            <gravity>1</gravity>
            <self_collide>0</self_collide>
            <kinematic>0</kinematic>
        </link>
        <link name="l_wrist">
            <pose>0.1752 0.000000 0.22479 0.000000 -0.000000 0.000000</pose>
            <inertial>
                <pose>-0.125700 -0.000000 0.000000 0.000000 -0.000000 0.000000</pose>
                <inertia>
                    <ixx>0.009</ixx>
                    <ixy>0.000000</ixy>
                    <ixz>0.000000</ixz>
                    <iyy>0.009</iyy>
                    <iyz>0.000000</iyz>
                    <izz>0.0014</izz>
                </inertia>
                <mass>1.4</mass>
            </inertial>
            <collision name="l_wrist_collision">
                <pose>-0.125700 -0.000000 0.000000 3.140000 -0.000000 0.000000</pose>
                <geometry>
                    <mesh>
                        <scale>1 1 1</scale>
                        <uri>model://Test_Wrist_m.STL</uri>
                    </mesh>
                </geometry>
                <surface>
                    <friction>
                        <ode>
                            <mu>1.000000</mu>
                            <mu2>1.000000</mu2>
                            <fdir1>0.000000 0.000000 0.000000</fdir1>
                            <slip1>0.000000</slip1>
                            <slip2>0.000000</slip2>
                        </ode>
                    </friction>
                    <bounce>
                        <restitution_coefficient>0.000000</restitution_coefficient>
                        <threshold>100000.000000</threshold>
                    </bounce>
                    <contact>
                        <ode>
                            <soft_cfm>0.0</soft_cfm>
                            <soft_erp>0.200000</soft_erp>
                            <kp>50000.000000</kp>
                            <kd>5000.000000</kd>
                            <max_vel>0.000000</max_vel>
                            <min_depth>0.001000</min_depth>
                        </ode>
                    </contact>
                </surface>
                <laser_retro>0.000000</laser_retro>
            </collision>
            <visual name="l_wrist_visual">
                <pose>-0.125700 -0.000000 0.000000 3.140000 -0.000000 0.000000</pose>
                <geometry>
                    <mesh>
                        <scale>1 1 1</scale>
                        <uri>model://Test_Wrist_m.STL</uri>
                    </mesh>
                </geometry>
                <material>
                    <diffuse>0.0 1.0 0.0 1</diffuse>
                </material>
                <cast_shadows>0</cast_shadows>
                <laser_retro>0.000000</laser_retro>
                <transparency>0.000000</transparency>
            </visual>
            <gravity>1</gravity>
            <self_collide>0</self_collide>
            <kinematic>0</kinematic>
        </link>
        <link name="l_hand">
            <pose>-0.0763 0.000000 0.22479 0.000000 -0.000000 0.000000</pose>
            <inertial>
                <pose>-0.105000 -0.000000 -0.000000 0.000000 -0.000000 0.000000</pose>
                <inertia>
                    <ixx>0.0013</ixx>
                    <ixy>0.000000</ixy>
                    <ixz>0.000000</ixz>
                    <iyy>0.0011</iyy>
                    <iyz>0.000000</iyz>
                    <izz>0.0004</izz>
                </inertia>
                <mass>0.5</mass>
            </inertial>
            <collision name="l_hand_collision">
                <pose>0.000000 -0.000000 -0.000000 3.140000 -0.000000 0.000000</pose>
                <geometry>
                    <mesh>
                        <scale>1 1 1</scale>
                        <uri>model://Test_Hand_m.STL</uri>
                    </mesh>
                </geometry>
                <surface>
                    <friction>
                        <ode>
                            <mu>1.000000</mu>
                            <mu2>1.000000</mu2>
                            <fdir1>0.000000 0.000000 0.000000</fdir1>
                            <slip1>0.000000</slip1>
                            <slip2>0.000000</slip2>
                        </ode>
                    </friction>
                    <bounce>
                        <restitution_coefficient>0.000000</restitution_coefficient>
                        <threshold>100000.000000</threshold>
                    </bounce>
                    <contact>
                        <ode>
                            <soft_cfm>0.0</soft_cfm>
                            <soft_erp>0.200000</soft_erp>
                            <kp>50000.000000</kp>
                            <kd>5000.000000</kd>
                            <max_vel>0.000000</max_vel>
                            <min_depth>0.001000</min_depth>
                        </ode>
                    </contact>
                </surface>
                <laser_retro>0.000000</laser_retro>
            </collision>
            <visual name="l_hand_visual">
                <pose>0.000000 -0.000000 -0.000000 3.140000 -0.000000 0.000000</pose>
                <geometry>
                    <mesh>
                        <scale>1 1 1</scale>
                        <uri>model://Test_Hand_m.STL</uri>
                    </mesh>
                </geometry>
                <material>
                    <diffuse>0.0 1.0 0.0 1</diffuse>
                </material>
                <cast_shadows>0</cast_shadows>
                <laser_retro>0.000000</laser_retro>
                <transparency>0.000000</transparency>
            </visual>
            <gravity>1</gravity>
            <self_collide>0</self_collide>
            <kinematic>0</kinematic>
        </link>
        <link name="neck">
            <pose>0.55372 0.000000 0.000000 0.000000 -0.000000 0.000000</pose>
            <inertial>
                <pose>0.065405 0.0 0.000000 0.000000 -0.000000 0.000000</pose>
                <inertia>
                    <ixx>0.0018</ixx>
                    <ixy>0.000000</ixy>
                    <ixz>0.000000</ixz>
                    <iyy>0.0022</iyy>
                    <iyz>0.000000</iyz>
                    <izz>0.0028</izz>
                </inertia>
                <mass>1.03</mass>
            </inertial>
            <collision name="neck_collision">
                <pose>0.000000 0.000000 0.000000 0.000000 -0.000000 0.000000</pose>
                <geometry>
                    <mesh>
                        <scale>1 1 1</scale>
                        <uri>model://Test_Neck_m.STL</uri>
                    </mesh>
                </geometry>
                <surface>
                    <friction>
                        <ode>
                            <mu>1.000000</mu>
                            <mu2>1.000000</mu2>
                            <fdir1>0.000000 0.000000 0.000000</fdir1>
                            <slip1>0.000000</slip1>
                            <slip2>0.000000</slip2>
                        </ode>
                    </friction>
                    <bounce>
                        <restitution_coefficient>0.000000</restitution_coefficient>
                        <threshold>100000.000000</threshold>
                    </bounce>
                    <contact>
                        <ode>
                            <soft_cfm>0.0</soft_cfm>
                            <soft_erp>0.200000</soft_erp>
                            <kp>50000.000000</kp>
                            <kd>5000.000000</kd>
                            <max_vel>0.000000</max_vel>
                            <min_depth>0.001000</min_depth>
                        </ode>
                    </contact>
                </surface>
                <laser_retro>0.000000</laser_retro>
            </collision>
            <visual name="neck_geom_visual">
                <pose>0.000000 0.000000 0.000000 0.000000 -0.000000 0.000000</pose>
                <geometry>
                    <mesh>
                        <scale>1 1 1</scale>
                        <uri>model://Test_Neck_m.STL</uri>
                    </mesh>
                </geometry>
                <material>
                    <diffuse>0.0 1.0 0.0 1</diffuse>
                </material>
                <cast_shadows>0</cast_shadows>
                <laser_retro>0.000000</laser_retro>
                <transparency>0.000000</transparency>
            </visual>
            <sensor name='neck_tactile_sensor' type='contact'>
                <contact>
                    <collision>neck_collision</collision>
                    <topic>__default_topic__</topic>
                </contact>
                <plugin name="ros_tactile_plugin" filename="libros_tactile_plugin.so" />
                <always_on>1</always_on>
                <update_rate>100.0</update_rate>
                <visualize>false</visualize>
            </sensor>
            <gravity>1</gravity>
            <self_collide>0</self_collide>
            <kinematic>0</kinematic>
        </link>
        <link name="head">
            <pose>0.6261 0.000000 0.000000 0.000000 0.000 0.000000</pose>
            <inertial>
                <pose>0.09779 0.0508 0.000000 0.000000 -0.000000 0.000000</pose>
                <inertia>
                    <ixx>0.0206</ixx>
                    <ixy>0.000000</ixy>
                    <ixz>0.000000</ixz>
                    <iyy>0.0235</iyy>
                    <iyz>0.000000</iyz>
                    <izz>0.0153</izz>
                </inertia>
                <mass>6.02</mass>
            </inertial>
            <collision name="head_collision">
                <pose>0.000000 0.000000 0.000000 0.000000 3.140000 0.000000</pose>
                <geometry>
                    <mesh>
                        <scale>1 1 1</scale>
                        <uri>model://Test_Head_m.STL</uri>
                    </mesh>
                </geometry>
                <surface>
                    <friction>
                        <ode>
                            <mu>1.000000</mu>
                            <mu2>1.000000</mu2>
                            <fdir1>0.000000 0.000000 0.000000</fdir1>
                            <slip1>0.000000</slip1>
                            <slip2>0.000000</slip2>
                        </ode>
                    </friction>
                    <bounce>
                        <restitution_coefficient>0.000000</restitution_coefficient>
                        <threshold>100000.000000</threshold>
                    </bounce>
                    <contact>
                        <ode>
                            <soft_cfm>0.0</soft_cfm>
                            <soft_erp>0.200000</soft_erp>
                            <kp>50000.000000</kp>
                            <kd>5000.000000</kd>
                            <max_vel>0.000000</max_vel>
                            <min_depth>0.001000</min_depth>
                        </ode>
                    </contact>
                </surface>
                <laser_retro>0.000000</laser_retro>
            </collision>
            <visual name="head_visual">
                <pose>0.000000 0.000000 0.000000 0.000000 3.140000 0.000000</pose>
                <geometry>
                    <mesh>
                        <scale>1 1 1</scale>
                        <uri>model://Test_Head_m.STL</uri>
                    </mesh>
                </geometry>
                <material>
                    <diffuse>0.0 1.0 0.0 1</diffuse>
                </material>
                <cast_shadows>0</cast_shadows>
                <laser_retro>0.000000</laser_retro>
                <transparency>0.000000</transparency>
            </visual>
            <sensor name='head_tactile_sensor' type='contact'>
                <contact>
                    <collision>head_collision</collision>
                    <topic>__default_topic__</topic>
                </contact>
                <plugin name="ros_tactile_plugin" filename="libros_tactile_plugin.so" />
                <always_on>1</always_on>
                <update_rate>100.0</update_rate>
                <visualize>false</visualize>
            </sensor>
            <gravity>1</gravity>
            <self_collide>0</self_collide>
            <kinematic>0</kinematic>
        </link>
        <link name="r_arm">
            <pose>0.4572 0.000000 -0.17526 0.000000 -0.000000 0.000000</pose>
            <inertial>
                <pose>-0.141005 0.000000 -0.04953 0.0 -0.000000 0.000000</pose>
                <inertia>
                    <ixx>0.0141</ixx>
                    <ixy>0.000000</ixy>
                    <ixz>0.000000</ixz>
                    <iyy>0.0141</iyy>
                    <iyz>0.000000</iyz>
                    <izz>0.0029</izz>
                </inertia>
                <mass>2.35</mass>
                <!--<mass>0.715</mass>-->
            </inertial>
            <collision name="r_arm_collision">
                <pose>-0.141005 0.000000 -0.04953 0.0 -0.000000 0.000000</pose>
                <geometry>
                    <mesh>
                        <scale>1 1 1</scale>
                        <uri>model://Test_Arm_m.STL</uri>
                    </mesh>
                </geometry>
                <surface>
                    <friction>
                        <ode>
                            <mu>1.000000</mu>
                            <mu2>1.000000</mu2>
                            <fdir1>0.000000 0.000000 0.000000</fdir1>
                            <slip1>0.000000</slip1>
                            <slip2>0.000000</slip2>
                        </ode>
                    </friction>
                    <bounce>
                        <restitution_coefficient>0.000000</restitution_coefficient>
                        <threshold>100000.000000</threshold>
                    </bounce>
                    <contact>
                        <ode>
                            <soft_cfm>0.0</soft_cfm>
                            <soft_erp>0.200000</soft_erp>
                            <kp>50000.000000</kp>
                            <kd>5000.000000</kd>
                            <max_vel>0.000000</max_vel>
                            <min_depth>0.001000</min_depth>
                        </ode>
                    </contact>
                </surface>
                <laser_retro>0.000000</laser_retro>
            </collision>
            <visual name="r_arm_visual">
                <pose>-0.141005 0.000000 -0.04953 0.0 -0.000000 0.000000</pose>
                <geometry>
                    <mesh>
                        <scale>1 1 1</scale>
                        <uri>model://Test_Arm_m.STL</uri>
                    </mesh>
                </geometry>
                <material>
                    <diffuse>0.0 1.0 0.0 1</diffuse>
                </material>
                <cast_shadows>0</cast_shadows>
                <laser_retro>0.000000</laser_retro>
                <transparency>0.000000</transparency>
            </visual>
            <gravity>1</gravity>
            <self_collide>0</self_collide>
            <kinematic>0</kinematic>
        </link>
        <link name="r_wrist">
            <pose>0.1752 0.000000 -0.22479 0.000000 -0.000000 0.000000</pose>
            <inertial>
                <pose>-0.125700 -0.000000 0.000000 0.000000 -0.000000 0.000000</pose>
                <inertia>
                    <ixx>0.009</ixx>
                    <ixy>0.000000</ixy>
                    <ixz>0.000000</ixz>
                    <iyy>0.009</iyy>
                    <iyz>0.000000</iyz>
                    <izz>0.0014</izz>
                </inertia>
                <mass>1.4</mass>
                <!--<mass>0.5</mass>-->
            </inertial>
            <collision name="r_wrist_collision">
                <pose>-0.125700 -0.000000 0.000000 0.000000 -0.000000 0.000000</pose>
                <geometry>
                    <mesh>
                        <scale>1 1 1</scale>
                        <uri>model://Test_Wrist_m.STL</uri>
                    </mesh>
                </geometry>
                <surface>
                    <friction>
                        <ode>
                            <mu>1.000000</mu>
                            <mu2>1.000000</mu2>
                            <fdir1>0.000000 0.000000 0.000000</fdir1>
                            <slip1>0.000000</slip1>
                            <slip2>0.000000</slip2>
                        </ode>
                    </friction>
                    <bounce>
                        <restitution_coefficient>0.000000</restitution_coefficient>
                        <threshold>100000.000000</threshold>
                    </bounce>
                    <contact>
                        <ode>
                            <soft_cfm>0.0</soft_cfm>
                            <soft_erp>0.200000</soft_erp>
                            <kp>50000.000000</kp>
                            <kd>5000.000000</kd>
                            <max_vel>0.000000</max_vel>
                            <min_depth>0.001000</min_depth>
                        </ode>
                    </contact>
                </surface>
                <laser_retro>0.000000</laser_retro>
            </collision>
            <visual name="r_wrist_visual">
                <pose>-0.125700 -0.000000 0.000000 0.000000 -0.000000 0.000000</pose>
                <geometry>
                    <mesh>
                        <scale>1 1 1</scale>
                        <uri>model://Test_Wrist_m.STL</uri>
                    </mesh>
                </geometry>
                <material>
                    <diffuse>0.0 1.0 0.0 1</diffuse>
                </material>
                <cast_shadows>0</cast_shadows>
                <laser_retro>0.000000</laser_retro>
                <transparency>0.000000</transparency>
            </visual>
            <gravity>1</gravity>
            <self_collide>0</self_collide>
            <kinematic>0</kinematic>
        </link>
        <link name="r_hand">
            <pose>-0.0763 0.000000 -0.22479 0.000000 -0.000000 0.000000</pose>
            <inertial>
                <pose>-0.105000 -0.000000 -0.000000 0.000000 -0.000000 0.000000</pose>
                <inertia>
                    <ixx>0.0013</ixx>
                    <ixy>0.000000</ixy>
                    <ixz>0.000000</ixz>
                    <iyy>0.0011</iyy>
                    <iyz>0.000000</iyz>
                    <izz>0.0004</izz>
                </inertia>
                <mass>0.5</mass>
                <!--<mass>0.177</mass>-->
            </inertial>
            <collision name="r_hand_collision">
                <pose>0.000000 -0.000000 -0.000000 0.000000 -0.000000 0.000000</pose>
                <geometry>
                    <mesh>
                        <scale>1 1 1</scale>
                        <uri>model://Test_Hand_m.STL</uri>
                    </mesh>
                </geometry>
                <surface>
                    <friction>
                        <ode>
                            <mu>1.000000</mu>
                            <mu2>1.000000</mu2>
                            <fdir1>0.000000 0.000000 0.000000</fdir1>
                            <slip1>0.000000</slip1>
                            <slip2>0.000000</slip2>
                        </ode>
                    </friction>
                    <bounce>
                        <restitution_coefficient>0.000000</restitution_coefficient>
                        <threshold>100000.000000</threshold>
                    </bounce>
                    <contact>
                        <ode>
                            <soft_cfm>0.0</soft_cfm>
                            <soft_erp>0.200000</soft_erp>
                            <kp>50000.000000</kp>
                            <kd>5000.000000</kd>
                            <max_vel>0.000000</max_vel>
                            <min_depth>0.001000</min_depth>
                        </ode>
                    </contact>
                </surface>
                <laser_retro>0.000000</laser_retro>
            </collision>
            <visual name="r_hand_visual">
                <pose>0.000000 -0.000000 -0.000000 0.000000 -0.000000 0.000000</pose>
                <geometry>
                    <mesh>
                        <scale>1 1 1</scale>
                        <uri>model://Test_Hand_m.STL</uri>
                    </mesh>
                </geometry>
                <material>
                    <diffuse>0.0 1.0 0.0 1</diffuse>
                </material>
                <cast_shadows>0</cast_shadows>
                <laser_retro>0.000000</laser_retro>
                <transparency>0.000000</transparency>
            </visual>
            <gravity>1</gravity>
            <self_collide>0</self_collide>
            <kinematic>0</kinematic>
        </link>
<!--Virtual Link-->
    <link name="v_r_arm">
        <pose>0.4572 0.000000 -0.17526 0.000000 -0.000000 0.000000</pose>
        <collision name="v_r_arm_collision">
            <geometry>
                <box>
                    <size>0.0 0.0 0.0</size>
                </box>
            </geometry>
        </collision>
    </link>
    <link name="v_l_arm">
        <pose>0.4572 0.000000 0.17526 3.140000 -0.000000 0.000000</pose>
        <collision name="v_l_arm_collision">
            <geometry>
                <box>
                    <size>0.0 0.0 0.0</size>
                </box>
            </geometry>
        </collision>    
    </link>
    <link name="v_l_thigh">
        <pose>0.000000 0.000000 0.0864 0.000000 -0.000000 0.000000</pose>
        <collision name="v_l_thigh_collision">
            <geometry>
                <box>
                    <size>0.0 0.0 0.0</size>
                </box>
            </geometry>
        </collision>    
    </link>
    <link name="v_r_thigh">
        <pose>0.000000 0.000000 -0.0864 0.000000 -0.000000 0.000000</pose>
        <collision name="v_r_thigh_collision">
            <geometry>
                <box>
                    <size>0.0 0.0 0.0</size>
                </box>
            </geometry>
        </collision>    
    </link>
        <joint name="l_thigh_joint" type="revolute">
            <child>v_l_thigh</child>
            <parent>lower_body</parent>
            <axis>
                <xyz>0.000000 0.000000 1.000000</xyz>
                <limit>
                    <lower>-2.051</lower>
                    <upper>0.785</upper>
                </limit>
                <dynamics>
                    <damping>1.000000</damping>
                </dynamics>
            </axis>
    </joint>
        <joint name="L_thigh_joint2" type="revolute">
            <child>l_thigh</child>
            <parent>v_l_thigh</parent>
            <axis>
                <xyz>0.000000 1.000000 0.000000</xyz>
                <limit>
                    <!--<lower>-0.698</lower>
                    <upper>0.780</upper>-->
                    <lower>0.</lower>
                    <upper>0.</upper>
                </limit>
                <dynamics>
                    <damping>1.000000</damping>
                </dynamics>
            </axis>
    </joint>
        <joint name="l_shin_joint" type="revolute">
        <child>l_shin</child>
            <parent>l_thigh</parent>
            <axis>
                <xyz>0.000000 0.000000 1.000000</xyz>
                <limit>
            <lower>0.</lower>
                    <upper>1.824</upper>
                </limit>
                <dynamics>
                    <damping>1.000000</damping>
                </dynamics>
            </axis>
        </joint>
        <joint name="l_foot_joint" type="revolute">
        <child>l_foot</child>
            <parent>l_shin</parent>
            <axis>
                <xyz>0.000000 0.000000 1.000000</xyz>
                <limit>
                    <lower>-0.410</lower>
                    <upper>0.633</upper>
        </limit>
                <dynamics>
                    <damping>1.000000</damping>
                </dynamics>
            </axis>
        </joint>
        <joint name="r_thigh_joint" type="revolute">
        <child>v_r_thigh</child>
            <parent>lower_body</parent>
            <axis>
                <xyz>0.000000 0.000000 1.000000</xyz>
                <limit>
                    <lower>-2.051</lower>
                    <upper>0.785</upper>
        </limit>
                <dynamics>
                    <damping>1.000000</damping>
                </dynamics>
            </axis>
    </joint>
       <joint name="R_thigh_joint2" type="revolute">
            <child>r_thigh</child>
            <parent>v_r_thigh</parent>
            <axis>
                <xyz>0.000000 1.000000 0.000000</xyz>
                <limit>
                    <!--<lower>-0.780</lower>
                    <upper>0.698</upper>-->
                    <lower>0.</lower>
                    <upper>0.</upper>
                </limit>
                <dynamics>
                    <damping>1.000000</damping>
                </dynamics>
            </axis>
    </joint>
        <joint name="r_shin_joint" type="revolute">
        <child>r_shin</child>
            <parent>r_thigh</parent>
            <axis>
                <xyz>0.000000 0.000000 1.000000</xyz>
                <limit>
                    <lower>0.</lower>
                    <upper>1.824</upper>
        </limit>
                <dynamics>
                    <damping>1.000000</damping>
                </dynamics>
            </axis>
        </joint>
        <joint name="r_foot_joint" type="revolute">
        <child>r_foot</child>
            <parent>r_shin</parent>
            <axis>
                <xyz>0.000000 0.000000 1.000000</xyz>
                <limit>
                    <lower>-0.410</lower>
                    <upper>0.633</upper>
        </limit>
                <dynamics>
                    <damping>1.000000</damping>
                </dynamics>
            </axis>
        </joint>
        <joint name="middle_body_joint" type="revolute">
        <child>middle_body</child>
            <parent>lower_body</parent>
            <axis>
                <xyz>0.000000 0.000000 1.000000</xyz>
                <limit>
                    <lower>-0.262</lower>
                    <upper>0.611</upper>
                </limit>
                <dynamics>
                    <damping>0.000000</damping>
                </dynamics>
            </axis>
        </joint>
    <joint name="upper_body_joint" type="revolute">
            <child>upper_body</child>
            <parent>middle_body</parent>
            <axis>
                <xyz>0.000000 0.000000 1.000000</xyz>
                <limit>
                    <lower>-0.262</lower>
                    <upper>0.611</upper>
                </limit>
                <dynamics>
                    <damping>0.000000</damping>
                </dynamics>
            </axis>
        </joint>
        <joint name="l_arm_joint" type="revolute">
        <child>v_l_arm</child>
            <parent>upper_body</parent>
            <axis>
                <xyz>0.000000 0.000000 1.000000</xyz>
                <limit>
            <lower>-3.094</lower>
                    <upper>1.025</upper>
            <!--<lower>-1.025</lower>
                    <upper>3.094</upper>-->
                </limit>
                <dynamics>
                    <damping>1.000000</damping>
                </dynamics>
            </axis>
        </joint>
        <joint name="L_arm_joint2" type="revolute">
        <child>l_arm</child>
            <parent>v_l_arm</parent>
            <axis>
                <xyz>0.000000 1.000000 0.000000</xyz>
                <limit>
            <lower>-0.0</lower>
                    <!--<upper>1.570</upper>-->
                    <upper>0.</upper>
                </limit>
                <dynamics>
                    <damping>1.000000</damping>
                </dynamics>
            </axis>
    </joint>
        <joint name="l_wrist_joint" type="revolute">
        <child>l_wrist</child>
            <parent>l_arm</parent>
            <axis>
                <xyz>0.000000 0.000000 1.000000</xyz>
                <limit>
            <lower>-2.378</lower>
                    <upper>0.</upper>
                    <!--<lower>0.</lower>
                    <upper>2.378</upper>-->
                </limit>
                <dynamics>
                    <damping>1.000000</damping>
                </dynamics>
            </axis>
        </joint>
        <joint name="l_hand_joint" type="revolute">
        <child>l_hand</child>
            <parent>l_wrist</parent>
            <axis>
                <xyz>0.000000 0.000000 1.000000</xyz>
                <limit>
            <!--<lower>-1.57</lower>-->
            <lower>0.</lower>
                    <upper>0.</upper>
                    <!--<upper>3.14</upper>-->
                </limit>
                <dynamics>
                    <damping>1.000000</damping>
                </dynamics>
            </axis>
        </joint>
        <joint name="neck_joint" type="revolute">
        <child>neck</child>
            <parent>upper_body</parent>
            <axis>
                <xyz>0.000000 0.000000 1.000000</xyz>
                <limit>
                    <!--<lower>-1.047000</lower>
                    <upper>1.047000</upper>-->
            <lower>0.000</lower>
                    <upper>0.000</upper>
                </limit>
                <dynamics>
                    <damping>0.000000</damping>
                </dynamics>
            </axis>
        </joint>
        <joint name="head_joint" type="revolute">
        <child>head</child>
            <parent>neck</parent>
            <axis>
                <xyz>0.000000 0.000000 1.000000</xyz>
                <limit>
                    <!--<lower>-1.047000</lower>
                    <upper>0.520000</upper>-->
            <lower>0.000</lower>
                    <upper>0.0000</upper>
                </limit>
                <dynamics>
                    <damping>0.000000</damping>
                </dynamics>
            </axis>
        </joint>
        <joint name="R_arm_joint2" type="revolute">
        <child>r_arm</child>
            <parent>v_r_arm</parent>
            <axis>
                <xyz>0.000000 1.000000 0.000000</xyz>
                <limit>
                    <!--<lower>-1.570</lower>-->
                    <lower>0.0</lower>
                    <upper>0.0</upper>
        </limit>
                <dynamics>
                    <damping>1.000000</damping>
                </dynamics>
            </axis>
        </joint>
        <joint name="r_arm_joint" type="revolute">
        <child>v_r_arm</child>
            <parent>upper_body</parent>
            <axis>
                <xyz>0.000000 0.000000 1.000000</xyz>
                <limit>
                    <lower>-3.094</lower>
                    <upper>1.025</upper>
        </limit>
                <dynamics>
                    <damping>1.000000</damping>
                </dynamics>
            </axis>
        </joint>
        <joint name="r_wrist_joint" type="revolute">
        <child>r_wrist</child>
            <parent>r_arm</parent>
            <axis>
                <xyz>0.000000 0.000000 1.000000</xyz>
                <limit>
                    <!--<lower>-2.378</lower>-->
                    <lower>0.</lower>
                    <upper>0.</upper>
        </limit>
                <dynamics>
                    <damping>1.000000</damping>
                </dynamics>
            </axis>
        </joint>
        <joint name="r_hand_joint" type="revolute">
        <child>r_hand</child>
            <parent>r_wrist</parent>
            <axis>
                <xyz>0.000000 0.000000 1.000000</xyz>
                <limit>
                    <!--<lower>-1.57</lower>-->
                    <lower>0.</lower>
                    <upper>0.</upper>
        </limit>
                <dynamics>
                    <damping>1.000000</damping>
                </dynamics>
            </axis>
        </joint>
        <static>0</static>
    <!--<gravity>1</gravity>
        <self_collide>0</self_collide>
        <kinematic>0</kinematic>-->
    <!--<plugin name="ros_ragdoll_model_plugin" filename="libros_ragdoll_model_plugin.so" />-->
    </model>
</sdf>